Workbook

Sheet Dashboard
B2: SYNTEGRA · Proje Takip Panosu
B3: Tüm değerler diğer sayfalardan formülle beslenir — elle güncelleme gerekmez.
B5: Toplam Proje | C5: Aktif Proje | D5: Geciken Proje | E5: Onay Bekleyen Mühendislik | F5: Arşen Onayı Bekleyen Teklif | G5: Tamamlanan Proje
B6: =COUNTA(Projeler!A2:A200) | C6: =COUNTA(Projeler!A2:A200)-COUNTIF(Projeler!G2:G200,"Tamamlandı")-COUNTIF(Projeler!G2:G200,"İptal") | D6: =COUNTIF(Projeler!I2:I200,"GECİKTİ") | E6: =COUNTIF(Muhendislik!B2:B200,"Onay Bekliyor") | F6: =COUNTIF(Teklifler!M2:M300,"bekliyor") | G6: =COUNTIF(Projeler!G2:G200,"Tamamlandı")
B9: Durum Dağılımı | E9: Eşikler (Listeler sayfasından değiştirilebilir)
B10: Taslak | C10: =COUNTIF(Projeler!G2:G200,"Taslak") | E10: EUR | F10: =Listeler!J2
B11: Onay Bekliyor | C11: =COUNTIF(Projeler!G2:G200,"Onay Bekliyor") | E11: TRY | F11: =Listeler!J3
B12: Mühendislik Sürecinde | C12: =COUNTIF(Projeler!G2:G200,"Mühendislik Sürecinde") | E12: USD | F12: =Listeler!J4
B13: Mühendislik Tamamlandı | C13: =COUNTIF(Projeler!G2:G200,"Mühendislik Tamamlandı")
B14: Satın Alma Sürecinde | C14: =COUNTIF(Projeler!G2:G200,"Satın Alma Sürecinde")
B15: Tamamlandı | C15: =COUNTIF(Projeler!G2:G200,"Tamamlandı")
B16: İptal | C16: =COUNTIF(Projeler!G2:G200,"İptal")
B18: Kullanım Notları
B19: 1. Projeler sayfasına her yeni projeyi girin — Kalan Gün ve Gecikme otomatik hesaplanır.
B20: 2. Mühendislik durumunu güncelleyin; Onaylandı olunca Ekipman ve Teklifler doldurulur.
B21: 3. Teklifler'de Kazanan = Evet işaretleyin — kümülatif eşik kontrolü otomatik çalışır.
B22: 4. 'ARŞEN ONAYI GEREKLİ' uyarısı çıkarsa Onay Durumu sütununu elle güncelleyin.
B23: 5. ZamanCizelgesi'ne başlangıç/bitiş girin — Gantt çubuğu kendiliğinden boyanır.
B24: 6. Örnek satırlar (ARS-2026-001-D) silinebilir.
B25: 7. Web uygulamasından veri aktarmak için: sayfadaki tabloyu kopyalayıp ilgili sekmeye yapıştırın.

Sheet Listeler
A1: P_DURUM | B1: M_DURUM | C1: T_ONAY | D1: T_DURUM | E1: PARA | F1: BODY | G1: EVETH | I1: EŞİKLER
A2: Taslak | B2: Taslak | E2: EUR | F2: Gaz Rezerv | I2: EUR | J2: 3000
A3: Onay Bekliyor | B3: Onay Bekliyor | C3: bekliyor | D3: Sipariş Verildi | E3: TRY | F3: Sıvı Rezerv | G3: Evet | I3: TRY | J3: 150000
A4: Mühendislik Sürecinde | B4: Onaylandı | C4: onaylandı | D4: Yolda | E4: USD | F4: Ekstraktör | G4: Hayır | I4: USD | J4: 3000
A5: Mühendislik Tamamlandı | B5: Revizyon İstendi | C5: reddedildi | D5: Teslim Alındı | F5: Seperatör
A6: Satın Alma Sürecinde | C6: doğrudan | D6: İptal | F6: Eşanjör
A7: Tamamlandı | F7: Yağ Kazanı
A8: İptal | F8: Ön Isıtıcı
F9: Pompa
F10: Kompresör
F11: Chiller
F12: Booster
F13: Borulama
F14: Vana
F15: Filtre
F16: BPR
F17: Otomasyon
F18: Sensörler

Sheet Projeler
A1: Proje Kodu | B1: Proje Adı | C1: Müşteri | D1: Sorumlu | E1: Başlangıç | F1: Termin | G1: Durum | H1: Kalan Gün | I1: Gecikme? | J1: Açıklama | K1: Oluşturan | L1: Oluşturma
A2: ARS-2026-001-D | B2: Örnek Proje (silinebilir) | C2: Deneme Müşteri | D2: Mirkan | E2: 46174 | F2: 46387 | G2: Mühendislik Sürecinde | H2: =IF($F2="","",$F2-TODAY()) | I2: =IF($F2="","",IF(AND($G2<>"Tamamlandı",$G2<>"İptal",$F2<TODAY()),"GECİKTİ","-"))
H3: =IF($F3="","",$F3-TODAY()) | I3: =IF($F3="","",IF(AND($G3<>"Tamamlandı",$G3<>"İptal",$F3<TODAY()),"GECİKTİ","-"))
H4: =IF($F4="","",$F4-TODAY()) | I4: =IF($F4="","",IF(AND($G4<>"Tamamlandı",$G4<>"İptal",$F4<TODAY()),"GECİKTİ","-"))
H5: =IF($F5="","",$F5-TODAY()) | I5: =IF($F5="","",IF(AND($G5<>"Tamamlandı",$G5<>"İptal",$F5<TODAY()),"GECİKTİ","-"))
H6: =IF($F6="","",$F6-TODAY()) | I6: =IF($F6="","",IF(AND($G6<>"Tamamlandı",$G6<>"İptal",$F6<TODAY()),"GECİKTİ","-"))
H7: =IF($F7="","",$F7-TODAY()) | I7: =IF($F7="","",IF(AND($G7<>"Tamamlandı",$G7<>"İptal",$F7<TODAY()),"GECİKTİ","-"))
H8: =IF($F8="","",$F8-TODAY()) | I8: =IF($F8="","",IF(AND($G8<>"Tamamlandı",$G8<>"İptal",$F8<TODAY()),"GECİKTİ","-"))
H9: =IF($F9="","",$F9-TODAY()) | I9: =IF($F9="","",IF(AND($G9<>"Tamamlandı",$G9<>"İptal",$F9<TODAY()),"GECİKTİ","-"))
H10: =IF($F10="","",$F10-TODAY()) | I10: =IF($F10="","",IF(AND($G10<>"Tamamlandı",$G10<>"İptal",$F10<TODAY()),"GECİKTİ","-"))
H11: =IF($F11="","",$F11-TODAY()) | I11: =IF($F11="","",IF(AND($G11<>"Tamamlandı",$G11<>"İptal",$F11<TODAY()),"GECİKTİ","-"))
H12: =IF($F12="","",$F12-TODAY()) | I12: =IF($F12="","",IF(AND($G12<>"Tamamlandı",$G12<>"İptal",$F12<TODAY()),"GECİKTİ","-"))
H13: =IF($F13="","",$F13-TODAY()) | I13: =IF($F13="","",IF(AND($G13<>"Tamamlandı",$G13<>"İptal",$F13<TODAY()),"GECİKTİ","-"))
H14: =IF($F14="","",$F14-TODAY()) | I14: =IF($F14="","",IF(AND($G14<>"Tamamlandı",$G14<>"İptal",$F14<TODAY()),"GECİKTİ","-"))
... H200: =IF($F200="","",$F200-TODAY()) | I200: =IF($F200="","",IF(AND($G200<>"Tamamlandı",$G200<>"İptal",$F200<TODAY()),"GECİKTİ","-"))

Sheet Muhendislik
A1: Proje Kodu | B1: Durum | C1: Revizyon Sayısı | D1: Son Gönderim | E1: Son Karar Veren | F1: Son Karar Tarihi | G1: Satın Alma Sorumlusu | H1: P&ID Yüklendi? | I1: Çizim Yüklendi? | J1: Not
A2: ARS-2026-001-D | B2: Onaylandı | C2: 1 | H2: Evet | I2: Evet

Sheet Ekipman
A1: Proje Kodu | B1: Gövde | C1: Alt Parça | D1: Adet | E1: Ölçü / Kapasite | F1: Malzeme Cinsi | G1: Malzeme Kalitesi | H1: Amaç | I1: Termin | J1: Üretim Termini | K1: Not
A2: ARS-2026-001-D | B2: Gaz Rezerv | C2: CO₂ Gaz Tankı Gövde | D2: 1 | E2: 500 L | F2: Paslanmaz Çelik | G2: 316L

Sheet Teklifler
A1: Proje Kodu | B1: Alt Parça | C1: Tedarikçi | D1: Fiyat | E1: Para Birimi | F1: Termin | G1: Ödeme | H1: Teslimat | I1: Kazanan? | J1: Tedarikçi Kümülatif | K1: Eşik | L1: Arşen Onayı Gerekli mi? | M1: Onay Durumu | N1: Onaylayan | O1: Onay Tarihi | P1: Sipariş Durumu | Q1: Not
A2: ARS-2026-001-D | B2: CO₂ Gaz Tankı Gövde | C2: Örnek Tedarikçi | D2: 4500 | E2: EUR | F2: 46280 | I2: Evet | J2: =IF(OR($C2="",$I2<>"Evet"),"",SUMIFS($D$2:$D$300,$A$2:$A$300,$A2,$C$2:$C$300,$C2,$E$2:$E$300,$E2,$I$2:$I$300,"Evet")) | K2: =IF($E2="","",VLOOKUP($E2,Listeler!$I$2:$J$4,2,0)) | L2: =IF($J2="","",IF($J2>$K2,"ARŞEN ONAYI GEREKLİ","Doğrudan geçer")) | M2: bekliyor
J3: =IF(OR($C3="",$I3<>"Evet"),"",SUMIFS($D$2:$D$300,$A$2:$A$300,$A3,$C$2:$C$300,$C3,$E$2:$E$300,$E3,$I$2:$I$300,"Evet")) | K3: =IF($E3="","",VLOOKUP($E3,Listeler!$I$2:$J$4,2,0)) | L3: =IF($J3="","",IF($J3>$K3,"ARŞEN ONAYI GEREKLİ","Doğrudan geçer"))
J4: =IF(OR($C4="",$I4<>"Evet"),"",SUMIFS($D$2:$D$300,$A$2:$A$300,$A4,$C$2:$C$300,$C4,$E$2:$E$300,$E4,$I$2:$I$300,"Evet")) | K4: =IF($E4="","",VLOOKUP($E4,Listeler!$I$2:$J$4,2,0)) | L4: =IF($J4="","",IF($J4>$K4,"ARŞEN ONAYI GEREKLİ","Doğrudan geçer"))
J5: =IF(OR($C5="",$I5<>"Evet"),"",SUMIFS($D$2:$D$300,$A$2:$A$300,$A5,$C$2:$C$300,$C5,$E$2:$E$300,$E5,$I$2:$I$300,"Evet")) | K5: =IF($E5="","",VLOOKUP($E5,Listeler!$I$2:$J$4,2,0)) | L5: =IF($J5="","",IF($J5>$K5,"ARŞEN ONAYI GEREKLİ","Doğrudan geçer"))
J6: =IF(OR($C6="",$I6<>"Evet"),"",SUMIFS($D$2:$D$300,$A$2:$A$300,$A6,$C$2:$C$300,$C6,$E$2:$E$300,$E6,$I$2:$I$300,"Evet")) | K6: =IF($E6="","",VLOOKUP($E6,Listeler!$I$2:$J$4,2,0)) | L6: =IF($J6="","",IF($J6>$K6,"ARŞEN ONAYI GEREKLİ","Doğrudan geçer"))
J7: =IF(OR($C7="",$I7<>"Evet"),"",SUMIFS($D$2:$D$300,$A$2:$A$300,$A7,$C$2:$C$300,$C7,$E$2:$E$300,$E7,$I$2:$I$300,"Evet")) | K7: =IF($E7="","",VLOOKUP($E7,Listeler!$I$2:$J$4,2,0)) | L7: =IF($J7="","",IF($J7>$K7,"ARŞEN ONAYI GEREKLİ","Doğrudan geçer"))
J8: =IF(OR($C8="",$I8<>"Evet"),"",SUMIFS($D$2:$D$300,$A$2:$A$300,$A8,$C$2:$C$300,$C8,$E$2:$E$300,$E8,$I$2:$I$300,"Evet")) | K8: =IF($E8="","",VLOOKUP($E8,Listeler!$I$2:$J$4,2,0)) | L8: =IF($J8="","",IF($J8>$K8,"ARŞEN ONAYI GEREKLİ","Doğrudan geçer"))
J9: =IF(OR($C9="",$I9<>"Evet"),"",SUMIFS($D$2:$D$300,$A$2:$A$300,$A9,$C$2:$C$300,$C9,$E$2:$E$300,$E9,$I$2:$I$300,"Evet")) | K9: =IF($E9="","",VLOOKUP($E9,Listeler!$I$2:$J$4,2,0)) | L9: =IF($J9="","",IF($J9>$K9,"ARŞEN ONAYI GEREKLİ","Doğrudan geçer"))
J10: =IF(OR($C10="",$I10<>"Evet"),"",SUMIFS($D$2:$D$300,$A$2:$A$300,$A10,$C$2:$C$300,$C10,$E$2:$E$300,$E10,$I$2:$I$300,"Evet")) | K10: =IF($E10="","",VLOOKUP($E10,Listeler!$I$2:$J$4,2,0)) | L10: =IF($J10="","",IF($J10>$K10,"ARŞEN ONAYI GEREKLİ","Doğrudan geçer"))
J11: =IF(OR($C11="",$I11<>"Evet"),"",SUMIFS($D$2:$D$300,$A$2:$A$300,$A11,$C$2:$C$300,$C11,$E$2:$E$300,$E11,$I$2:$I$300,"Evet")) | K11: =IF($E11="","",VLOOKUP($E11,Listeler!$I$2:$J$4,2,0)) | L11: =IF($J11="","",IF($J11>$K11,"ARŞEN ONAYI GEREKLİ","Doğrudan geçer"))
J12: =IF(OR($C12="",$I12<>"Evet"),"",SUMIFS($D$2:$D$300,$A$2:$A$300,$A12,$C$2:$C$300,$C12,$E$2:$E$300,$E12,$I$2:$I$300,"Evet")) | K12: =IF($E12="","",VLOOKUP($E12,Listeler!$I$2:$J$4,2,0)) | L12: =IF($J12="","",IF($J12>$K12,"ARŞEN ONAYI GEREKLİ","Doğrudan geçer"))
J13: =IF(OR($C13="",$I13<>"Evet"),"",SUMIFS($D$2:$D$300,$A$2:$A$300,$A13,$C$2:$C$300,$C13,$E$2:$E$300,$E13,$I$2:$I$300,"Evet")) | K13: =IF($E13="","",VLOOKUP($E13,Listeler!$I$2:$J$4,2,0)) | L13: =IF($J13="","",IF($J13>$K13,"ARŞEN ONAYI GEREKLİ","Doğrudan geçer"))
J14: =IF(OR($C14="",$I14<>"Evet"),"",SUMIFS($D$2:$D$300,$A$2:$A$300,$A14,$C$2:$C$300,$C14,$E$2:$E$300,$E14,$I$2:$I$300,"Evet")) | K14: =IF($E14="","",VLOOKUP($E14,Listeler!$I$2:$J$4,2,0)) | L14: =IF($J14="","",IF($J14>$K14,"ARŞEN ONAYI GEREKLİ","Doğrudan geçer"))
... J300: =IF(OR($C300="",$I300<>"Evet"),"",SUMIFS($D$2:$D$300,$A$2:$A$300,$A300,$C$2:$C$300,$C300,$E$2:$E$300,$E300,$I$2:$I$300,"Evet")) | K300: =IF($E300="","",VLOOKUP($E300,Listeler!$I$2:$J$4,2,0)) | L300: =IF($J300="","",IF($J300>$K300,"ARŞEN ONAYI GEREKLİ","Doğrudan geçer"))

Sheet ZamanCizelgesi
A1: Yıl: | B1: 2026 | D1: Başlangıç ve bitiş tarihlerini girin — çubuklar otomatik boyanır.
A2: Proje Kodu | B2: Aşama | C2: Başlangıç | D2: Bitiş | E2: 1 | F2: 2 | G2: 3 | H2: 4 | I2: 5 | J2: 6 | K2: 7 | L2: 8 | M2: 9 | N2: 10 | O2: 11 | P2: 12 | Q2: 13 | R2: 14 | S2: 15 | T2: 16 | U2: 17 | V2: 18 | W2: 19 | X2: 20 | Y2: 21 | Z2: 22 | AA2: 23 | AB2: 24 | AC2: 25 | AD2: 26 | AE2: 27 | AF2: 28 | AG2: 29 | AH2: 30 | AI2: 31 | AJ2: 32 | AK2: 33 | AL2: 34 | AM2: 35 | AN2: 36 | AO2: 37 | AP2: 38 | AQ2: 39 | AR2: 40 | AS2: 41 | AT2: 42 | AU2: 43 | AV2: 44 | AW2: 45 | AX2: 46 | AY2: 47 | AZ2: 48 | BA2: 49 | BB2: 50 | BC2: 51 | BD2: 52 | BE2: 53 | BF2: 54
A3: ARS-2026-001-D | B3: Mühendislik | C3: 46174 | D3: 46201 | E3: =IF(OR($C3="",$D3=""),"",IF(AND(DATE($B$1,1,1)+(1-1)*7<=$D3,DATE($B$1,1,1)+1*7-1>=$C3),1,"")) | F3: =IF(OR($C3="",$D3=""),"",IF(AND(DATE($B$1,1,1)+(2-1)*7<=$D3,DATE($B$1,1,1)+2*7-1>=$C3),1,"")) | G3: =IF(OR($C3="",$D3=""),"",IF(AND(DATE($B$1,1,1)+(3-1)*7<=$D3,DATE($B$1,1,1)+3*7-1>=$C3),1,"")) | H3: =IF(OR($C3="",$D3=""),"",IF(AND(DATE($B$1,1,1)+(4-1)*7<=$D3,DATE($B$1,1,1)+4*7-1>=$C3),1,"")) | I3: =IF(OR($C3="",$D3=""),"",IF(AND(DATE($B$1,1,1)+(5-1)*7<=$D3,DATE($B$1,1,1)+5*7-1>=$C3),1,"")) | J3: =IF(OR($C3="",$D3=""),"",IF(AND(DATE($B$1,1,1)+(6-1)*7<=$D3,DATE($B$1,1,1)+6*7-1>=$C3),1,"")) | K3: =IF(OR($C3="",$D3=""),"",IF(AND(DATE($B$1,1,1)+(7-1)*7<=$D3,DATE($B$1,1,1)+7*7-1>=$C3),1,"")) | L3: =IF(OR($C3="",$D3=""),"",IF(AND(DATE($B$1,1,1)+(8-1)*7<=$D3,DATE($B$1,1,1)+8*7-1>=$C3),1,"")) | M3: =IF(OR($C3="",$D3=""),"",IF(AND(DATE($B$1,1,1)+(9-1)*7<=$D3,DATE($B$1,1,1)+9*7-1>=$C3),1,"")) | N3: =IF(OR($C3="",$D3=""),"",IF(AND(DATE($B$1,1,1)+(10-1)*7<=$D3,DATE($B$1,1,1)+10*7-1>=$C3),1,"")) | O3: =IF(OR($C3="",$D3=""),"",IF(AND(DATE($B$1,1,1)+(11-1)*7<=$D3,DATE($B$1,1,1)+11*7-1>=$C3),1,"")) | P3: =IF(OR($C3="",$D3=""),"",IF(AND(DATE($B$1,1,1)+(12-1)*7<=$D3,DATE($B$1,1,1)+12*7-1>=$C3),1,"")) | Q3: =IF(OR($C3="",$D3=""),"",IF(AND(DATE($B$1,1,1)+(13-1)*7<=$D3,DATE($B$1,1,1)+13*7-1>=$C3),1,"")) | R3: =IF(OR($C3="",$D3=""),"",IF(AND(DATE($B$1,1,1)+(14-1)*7<=$D3,DATE($B$1,1,1)+14*7-1>=$C3),1,"")) | S3: =IF(OR($C3="",$D3=""),"",IF(AND(DATE($B$1,1,1)+(15-1)*7<=$D3,DATE($B$1,1,1)+15*7-1>=$C3),1,"")) | T3: =IF(OR($C3="",$D3=""),"",IF(AND(DATE($B$1,1,1)+(16-1)*7<=$D3,DATE($B$1,1,1)+16*7-1>=$C3),1,"")) | U3: =IF(OR($C3="",$D3=""),"",IF(AND(DATE($B$1,1,1)+(17-1)*7<=$D3,DATE($B$1,1,1)+17*7-1>=$C3),1,"")) | V3: =IF(OR($C3="",$D3=""),"",IF(AND(DATE($B$1,1,1)+(18-1)*7<=$D3,DATE($B$1,1,1)+18*7-1>=$C3),1,"")) | W3: =IF(OR($C3="",$D3=""),"",IF(AND(DATE($B$1,1,1)+(19-1)*7<=$D3,DATE($B$1,1,1)+19*7-1>=$C3),1,"")) | X3: =IF(OR($C3="",$D3=""),"",IF(AND(DATE($B$1,1,1)+(20-1)*7<=$D3,DATE($B$1,1,1)+20*7-1>=$C3),1,"")) | Y3: =IF(OR($C3="",$D3=""),"",IF(AND(DATE($B$1,1,1)+(21-1)*7<=$D3,DATE($B$1,1,1)+21*7-1>=$C3),1,"")) | Z3: =IF(OR($C3="",$D3=""),"",IF(AND(DATE($B$1,1,1)+(22-1)*7<=$D3,DATE($B$1,1,1)+22*7-1>=$C3),1,"")) | AA3: =IF(OR($C3="",$D3=""),"",IF(AND(DATE($B$1,1,1)+(23-1)*7<=$D3,DATE($B$1,1,1)+23*7-1>=$C3),1,"")) | AB3: =IF(OR($C3="",$D3=""),"",IF(AND(DATE($B$1,1,1)+(24-1)*7<=$D3,DATE($B$1,1,1)+24*7-1>=$C3),1,"")) | AC3: =IF(OR($C3="",$D3=""),"",IF(AND(DATE($B$1,1,1)+(25-1)*7<=$D3,DATE($B$1,1,1)+25*7-1>=$C3),1,"")) | AD3: =IF(OR($C3="",$D3=""),"",IF(AND(DATE($B$1,1,1)+(26-1)*7<=$D3,DATE($B$1,1,1)+26*7-1>=$C3),1,"")) | AE3: =IF(OR($C3="",$D3=""),"",IF(AND(DATE($B$1,1,1)+(27-1)*7<=$D3,DATE($B$1,1,1)+27*7-1>=$C3),1,"")) | AF3: =IF(OR($C3="",$D3=""),"",IF(AND(DATE($B$1,1,1)+(28-1)*7<=$D3,DATE($B$1,1,1)+28*7-1>=$C3),1,"")) | AG3: =IF(OR($C3="",$D3=""),"",IF(AND(DATE($B$1,1,1)+(29-1)*7<=$D3,DATE($B$1,1,1)+29*7-1>=$C3),1,"")) | AH3: =IF(OR($C3="",$D3=""),"",IF(AND(DATE($B$1,1,1)+(30-1)*7<=$D3,DATE($B$1,1,1)+30*7-1>=$C3),1,"")) | AI3: =IF(OR($C3="",$D3=""),"",IF(AND(DATE($B$1,1,1)+(31-1)*7<=$D3,DATE($B$1,1,1)+31*7-1>=$C3),1,"")) | AJ3: =IF(OR($C3="",$D3=""),"",IF(AND(DATE($B$1,1,1)+(32-1)*7<=$D3,DATE($B$1,1,1)+32*7-1>=$C3),1,"")) | AK3: =IF(OR($C3="",$D3=""),"",IF(AND(DATE($B$1,1,1)+(33-1)*7<=$D3,DATE($B$1,1,1)+33*7-1>=$C3),1,"")) | AL3: =IF(OR($C3="",$D3=""),"",IF(AND(DATE($B$1,1,1)+(34-1)*7<=$D3,DATE($B$1,1,1)+34*7-1>=$C3),1,"")) | AM3: =IF(OR($C3="",$D3=""),"",IF(AND(DATE($B$1,1,1)+(35-1)*7<=$D3,DATE($B$1,1,1)+35*7-1>=$C3),1,"")) | AN3: =IF(OR($C3="",$D3=""),"",IF(AND(DATE($B$1,1,1)+(36-1)*7<=$D3,DATE($B$1,1,1)+36*7-1>=$C3),1,"")) | AO3: =IF(OR($C3="",$D3=""),"",IF(AND(DATE($B$1,1,1)+(37-1)*7<=$D3,DATE($B$1,1,1)+37*7-1>=$C3),1,"")) | AP3: =IF(OR($C3="",$D3=""),"",IF(AND(DATE($B$1,1,1)+(38-1)*7<=$D3,DATE($B$1,1,1)+38*7-1>=$C3),1,"")) | AQ3: =IF(OR($C3="",$D3=""),"",IF(AND(DATE($B$1,1,1)+(39-1)*7<=$D3,DATE($B$1,1,1)+39*7-1>=$C3),1,"")) | AR3: =IF(OR($C3="",$D3=""),"",IF(AND(DATE($B$1,1,1)+(40-1)*7<=$D3,DATE($B$1,1,1)+40*7-1>=$C3),1,"")) | AS3: =IF(OR($C3="",$D3=""),"",IF(AND(DATE($B$1,1,1)+(41-1)*7<=$D3,DATE($B$1,1,1)+41*7-1>=$C3),1,"")) | AT3: =IF(OR($C3="",$D3=""),"",IF(AND(DATE($B$1,1,1)+(42-1)*7<=$D3,DATE($B$1,1,1)+42*7-1>=$C3),1,"")) | AU3: =IF(OR($C3="",$D3=""),"",IF(AND(DATE($B$1,1,1)+(43-1)*7<=$D3,DATE($B$1,1,1)+43*7-1>=$C3),1,"")) | AV3: =IF(OR($C3="",$D3=""),"",IF(AND(DATE($B$1,1,1)+(44-1)*7<=$D3,DATE($B$1,1,1)+44*7-1>=$C3),1,"")) | AW3: =IF(OR($C3="",$D3=""),"",IF(AND(DATE($B$1,1,1)+(45-1)*7<=$D3,DATE($B$1,1,1)+45*7-1>=$C3),1,"")) | AX3: =IF(OR($C3="",$D3=""),"",IF(AND(DATE($B$1,1,1)+(46-1)*7<=$D3,DATE($B$1,1,1)+46*7-1>=$C3),1,"")) | AY3: =IF(OR($C3="",$D3=""),"",IF(AND(DATE($B$1,1,1)+(47-1)*7<=$D3,DATE($B$1,1,1)+47*7-1>=$C3),1,"")) | AZ3: =IF(OR($C3="",$D3=""),"",IF(AND(DATE($B$1,1,1)+(48-1)*7<=$D3,DATE($B$1,1,1)+48*7-1>=$C3),1,"")) | BA3: =IF(OR($C3="",$D3=""),"",IF(AND(DATE($B$1,1,1)+(49-1)*7<=$D3,DATE($B$1,1,1)+49*7-1>=$C3),1,"")) | BB3: =IF(OR($C3="",$D3=""),"",IF(AND(DATE($B$1,1,1)+(50-1)*7<=$D3,DATE($B$1,1,1)+50*7-1>=$C3),1,"")) | BC3: =IF(OR($C3="",$D3=""),"",IF(AND(DATE($B$1,1,1)+(51-1)*7<=$D3,DATE($B$1,1,1)+51*7-1>=$C3),1,"")) | BD3: =IF(OR($C3="",$D3=""),"",IF(AND(DATE($B$1,1,1)+(52-1)*7<=$D3,DATE($B$1,1,1)+52*7-1>=$C3),1,"")) | BE3: =IF(OR($C3="",$D3=""),"",IF(AND(DATE($B$1,1,1)+(53-1)*7<=$D3,DATE($B$1,1,1)+53*7-1>=$C3),1,"")) | BF3: =IF(OR($C3="",$D3=""),"",IF(AND(DATE($B$1,1,1)+(54-1)*7<=$D3,DATE($B$1,1,1)+54*7-1>=$C3),1,""))
A4: ARS-2026-001-D | B4: Satın Alma | C4: 46204 | D4: 46280 | E4: =IF(OR($C4="",$D4=""),"",IF(AND(DATE($B$1,1,1)+(1-1)*7<=$D4,DATE($B$1,1,1)+1*7-1>=$C4),1,"")) | F4: =IF(OR($C4="",$D4=""),"",IF(AND(DATE($B$1,1,1)+(2-1)*7<=$D4,DATE($B$1,1,1)+2*7-1>=$C4),1,"")) | G4: =IF(OR($C4="",$D4=""),"",IF(AND(DATE($B$1,1,1)+(3-1)*7<=$D4,DATE($B$1,1,1)+3*7-1>=$C4),1,"")) | H4: =IF(OR($C4="",$D4=""),"",IF(AND(DATE($B$1,1,1)+(4-1)*7<=$D4,DATE($B$1,1,1)+4*7-1>=$C4),1,"")) | I4: =IF(OR($C4="",$D4=""),"",IF(AND(DATE($B$1,1,1)+(5-1)*7<=$D4,DATE($B$1,1,1)+5*7-1>=$C4),1,"")) | J4: =IF(OR($C4="",$D4=""),"",IF(AND(DATE($B$1,1,1)+(6-1)*7<=$D4,DATE($B$1,1,1)+6*7-1>=$C4),1,"")) | K4: =IF(OR($C4="",$D4=""),"",IF(AND(DATE($B$1,1,1)+(7-1)*7<=$D4,DATE($B$1,1,1)+7*7-1>=$C4),1,"")) | L4: =IF(OR($C4="",$D4=""),"",IF(AND(DATE($B$1,1,1)+(8-1)*7<=$D4,DATE($B$1,1,1)+8*7-1>=$C4),1,"")) | M4: =IF(OR($C4="",$D4=""),"",IF(AND(DATE($B$1,1,1)+(9-1)*7<=$D4,DATE($B$1,1,1)+9*7-1>=$C4),1,"")) | N4: =IF(OR($C4="",$D4=""),"",IF(AND(DATE($B$1,1,1)+(10-1)*7<=$D4,DATE($B$1,1,1)+10*7-1>=$C4),1,"")) | O4: =IF(OR($C4="",$D4=""),"",IF(AND(DATE($B$1,1,1)+(11-1)*7<=$D4,DATE($B$1,1,1)+11*7-1>=$C4),1,"")) | P4: =IF(OR($C4="",$D4=""),"",IF(AND(DATE($B$1,1,1)+(12-1)*7<=$D4,DATE($B$1,1,1)+12*7-1>=$C4),1,"")) | Q4: =IF(OR($C4="",$D4=""),"",IF(AND(DATE($B$1,1,1)+(13-1)*7<=$D4,DATE($B$1,1,1)+13*7-1>=$C4),1,"")) | R4: =IF(OR($C4="",$D4=""),"",IF(AND(DATE($B$1,1,1)+(14-1)*7<=$D4,DATE($B$1,1,1)+14*7-1>=$C4),1,"")) | S4: =IF(OR($C4="",$D4=""),"",IF(AND(DATE($B$1,1,1)+(15-1)*7<=$D4,DATE($B$1,1,1)+15*7-1>=$C4),1,"")) | T4: =IF(OR($C4="",$D4=""),"",IF(AND(DATE($B$1,1,1)+(16-1)*7<=$D4,DATE($B$1,1,1)+16*7-1>=$C4),1,"")) | U4: =IF(OR($C4="",$D4=""),"",IF(AND(DATE($B$1,1,1)+(17-1)*7<=$D4,DATE($B$1,1,1)+17*7-1>=$C4),1,"")) | V4: =IF(OR($C4="",$D4=""),"",IF(AND(DATE($B$1,1,1)+(18-1)*7<=$D4,DATE($B$1,1,1)+18*7-1>=$C4),1,"")) | W4: =IF(OR($C4="",$D4=""),"",IF(AND(DATE($B$1,1,1)+(19-1)*7<=$D4,DATE($B$1,1,1)+19*7-1>=$C4),1,"")) | X4: =IF(OR($C4="",$D4=""),"",IF(AND(DATE($B$1,1,1)+(20-1)*7<=$D4,DATE($B$1,1,1)+20*7-1>=$C4),1,"")) | Y4: =IF(OR($C4="",$D4=""),"",IF(AND(DATE($B$1,1,1)+(21-1)*7<=$D4,DATE($B$1,1,1)+21*7-1>=$C4),1,"")) | Z4: =IF(OR($C4="",$D4=""),"",IF(AND(DATE($B$1,1,1)+(22-1)*7<=$D4,DATE($B$1,1,1)+22*7-1>=$C4),1,"")) | AA4: =IF(OR($C4="",$D4=""),"",IF(AND(DATE($B$1,1,1)+(23-1)*7<=$D4,DATE($B$1,1,1)+23*7-1>=$C4),1,"")) | AB4: =IF(OR($C4="",$D4=""),"",IF(AND(DATE($B$1,1,1)+(24-1)*7<=$D4,DATE($B$1,1,1)+24*7-1>=$C4),1,"")) | AC4: =IF(OR($C4="",$D4=""),"",IF(AND(DATE($B$1,1,1)+(25-1)*7<=$D4,DATE($B$1,1,1)+25*7-1>=$C4),1,"")) | AD4: =IF(OR($C4="",$D4=""),"",IF(AND(DATE($B$1,1,1)+(26-1)*7<=$D4,DATE($B$1,1,1)+26*7-1>=$C4),1,"")) | AE4: =IF(OR($C4="",$D4=""),"",IF(AND(DATE($B$1,1,1)+(27-1)*7<=$D4,DATE($B$1,1,1)+27*7-1>=$C4),1,"")) | AF4: =IF(OR($C4="",$D4=""),"",IF(AND(DATE($B$1,1,1)+(28-1)*7<=$D4,DATE($B$1,1,1)+28*7-1>=$C4),1,"")) | AG4: =IF(OR($C4="",$D4=""),"",IF(AND(DATE($B$1,1,1)+(29-1)*7<=$D4,DATE($B$1,1,1)+29*7-1>=$C4),1,"")) | AH4: =IF(OR($C4="",$D4=""),"",IF(AND(DATE($B$1,1,1)+(30-1)*7<=$D4,DATE($B$1,1,1)+30*7-1>=$C4),1,"")) | AI4: =IF(OR($C4="",$D4=""),"",IF(AND(DATE($B$1,1,1)+(31-1)*7<=$D4,DATE($B$1,1,1)+31*7-1>=$C4),1,"")) | AJ4: =IF(OR($C4="",$D4=""),"",IF(AND(DATE($B$1,1,1)+(32-1)*7<=$D4,DATE($B$1,1,1)+32*7-1>=$C4),1,"")) | AK4: =IF(OR($C4="",$D4=""),"",IF(AND(DATE($B$1,1,1)+(33-1)*7<=$D4,DATE($B$1,1,1)+33*7-1>=$C4),1,"")) | AL4: =IF(OR($C4="",$D4=""),"",IF(AND(DATE($B$1,1,1)+(34-1)*7<=$D4,DATE($B$1,1,1)+34*7-1>=$C4),1,"")) | AM4: =IF(OR($C4="",$D4=""),"",IF(AND(DATE($B$1,1,1)+(35-1)*7<=$D4,DATE($B$1,1,1)+35*7-1>=$C4),1,"")) | AN4: =IF(OR($C4="",$D4=""),"",IF(AND(DATE($B$1,1,1)+(36-1)*7<=$D4,DATE($B$1,1,1)+36*7-1>=$C4),1,"")) | AO4: =IF(OR($C4="",$D4=""),"",IF(AND(DATE($B$1,1,1)+(37-1)*7<=$D4,DATE($B$1,1,1)+37*7-1>=$C4),1,"")) | AP4: =IF(OR($C4="",$D4=""),"",IF(AND(DATE($B$1,1,1)+(38-1)*7<=$D4,DATE($B$1,1,1)+38*7-1>=$C4),1,"")) | AQ4: =IF(OR($C4="",$D4=""),"",IF(AND(DATE($B$1,1,1)+(39-1)*7<=$D4,DATE($B$1,1,1)+39*7-1>=$C4),1,"")) | AR4: =IF(OR($C4="",$D4=""),"",IF(AND(DATE($B$1,1,1)+(40-1)*7<=$D4,DATE($B$1,1,1)+40*7-1>=$C4),1,"")) | AS4: =IF(OR($C4="",$D4=""),"",IF(AND(DATE($B$1,1,1)+(41-1)*7<=$D4,DATE($B$1,1,1)+41*7-1>=$C4),1,"")) | AT4: =IF(OR($C4="",$D4=""),"",IF(AND(DATE($B$1,1,1)+(42-1)*7<=$D4,DATE($B$1,1,1)+42*7-1>=$C4),1,"")) | AU4: =IF(OR($C4="",$D4=""),"",IF(AND(DATE($B$1,1,1)+(43-1)*7<=$D4,DATE($B$1,1,1)+43*7-1>=$C4),1,"")) | AV4: =IF(OR($C4="",$D4=""),"",IF(AND(DATE($B$1,1,1)+(44-1)*7<=$D4,DATE($B$1,1,1)+44*7-1>=$C4),1,"")) | AW4: =IF(OR($C4="",$D4=""),"",IF(AND(DATE($B$1,1,1)+(45-1)*7<=$D4,DATE($B$1,1,1)+45*7-1>=$C4),1,"")) | AX4: =IF(OR($C4="",$D4=""),"",IF(AND(DATE($B$1,1,1)+(46-1)*7<=$D4,DATE($B$1,1,1)+46*7-1>=$C4),1,"")) | AY4: =IF(OR($C4="",$D4=""),"",IF(AND(DATE($B$1,1,1)+(47-1)*7<=$D4,DATE($B$1,1,1)+47*7-1>=$C4),1,"")) | AZ4: =IF(OR($C4="",$D4=""),"",IF(AND(DATE($B$1,1,1)+(48-1)*7<=$D4,DATE($B$1,1,1)+48*7-1>=$C4),1,"")) | BA4: =IF(OR($C4="",$D4=""),"",IF(AND(DATE($B$1,1,1)+(49-1)*7<=$D4,DATE($B$1,1,1)+49*7-1>=$C4),1,"")) | BB4: =IF(OR($C4="",$D4=""),"",IF(AND(DATE($B$1,1,1)+(50-1)*7<=$D4,DATE($B$1,1,1)+50*7-1>=$C4),1,"")) | BC4: =IF(OR($C4="",$D4=""),"",IF(AND(DATE($B$1,1,1)+(51-1)*7<=$D4,DATE($B$1,1,1)+51*7-1>=$C4),1,"")) | BD4: =IF(OR($C4="",$D4=""),"",IF(AND(DATE($B$1,1,1)+(52-1)*7<=$D4,DATE($B$1,1,1)+52*7-1>=$C4),1,"")) | BE4: =IF(OR($C4="",$D4=""),"",IF(AND(DATE($B$1,1,1)+(53-1)*7<=$D4,DATE($B$1,1,1)+53*7-1>=$C4),1,"")) | BF4: =IF(OR($C4="",$D4=""),"",IF(AND(DATE($B$1,1,1)+(54-1)*7<=$D4,DATE($B$1,1,1)+54*7-1>=$C4),1,""))
E5: =IF(OR($C5="",$D5=""),"",IF(AND(DATE($B$1,1,1)+(1-1)*7<=$D5,DATE($B$1,1,1)+1*7-1>=$C5),1,"")) | F5: =IF(OR($C5="",$D5=""),"",IF(AND(DATE($B$1,1,1)+(2-1)*7<=$D5,DATE($B$1,1,1)+2*7-1>=$C5),1,"")) | G5: =IF(OR($C5="",$D5=""),"",IF(AND(DATE($B$1,1,1)+(3-1)*7<=$D5,DATE($B$1,1,1)+3*7-1>=$C5),1,"")) | H5: =IF(OR($C5="",$D5=""),"",IF(AND(DATE($B$1,1,1)+(4-1)*7<=$D5,DATE($B$1,1,1)+4*7-1>=$C5),1,"")) | I5: =IF(OR($C5="",$D5=""),"",IF(AND(DATE($B$1,1,1)+(5-1)*7<=$D5,DATE($B$1,1,1)+5*7-1>=$C5),1,"")) | J5: =IF(OR($C5="",$D5=""),"",IF(AND(DATE($B$1,1,1)+(6-1)*7<=$D5,DATE($B$1,1,1)+6*7-1>=$C5),1,"")) | K5: =IF(OR($C5="",$D5=""),"",IF(AND(DATE($B$1,1,1)+(7-1)*7<=$D5,DATE($B$1,1,1)+7*7-1>=$C5),1,"")) | L5: =IF(OR($C5="",$D5=""),"",IF(AND(DATE($B$1,1,1)+(8-1)*7<=$D5,DATE($B$1,1,1)+8*7-1>=$C5),1,"")) | M5: =IF(OR($C5="",$D5=""),"",IF(AND(DATE($B$1,1,1)+(9-1)*7<=$D5,DATE($B$1,1,1)+9*7-1>=$C5),1,"")) | N5: =IF(OR($C5="",$D5=""),"",IF(AND(DATE($B$1,1,1)+(10-1)*7<=$D5,DATE($B$1,1,1)+10*7-1>=$C5),1,"")) | O5: =IF(OR($C5="",$D5=""),"",IF(AND(DATE($B$1,1,1)+(11-1)*7<=$D5,DATE($B$1,1,1)+11*7-1>=$C5),1,"")) | P5: =IF(OR($C5="",$D5=""),"",IF(AND(DATE($B$1,1,1)+(12-1)*7<=$D5,DATE($B$1,1,1)+12*7-1>=$C5),1,"")) | Q5: =IF(OR($C5="",$D5=""),"",IF(AND(DATE($B$1,1,1)+(13-1)*7<=$D5,DATE($B$1,1,1)+13*7-1>=$C5),1,"")) | R5: =IF(OR($C5="",$D5=""),"",IF(AND(DATE($B$1,1,1)+(14-1)*7<=$D5,DATE($B$1,1,1)+14*7-1>=$C5),1,"")) | S5: =IF(OR($C5="",$D5=""),"",IF(AND(DATE($B$1,1,1)+(15-1)*7<=$D5,DATE($B$1,1,1)+15*7-1>=$C5),1,"")) | T5: =IF(OR($C5="",$D5=""),"",IF(AND(DATE($B$1,1,1)+(16-1)*7<=$D5,DATE($B$1,1,1)+16*7-1>=$C5),1,"")) | U5: =IF(OR($C5="",$D5=""),"",IF(AND(DATE($B$1,1,1)+(17-1)*7<=$D5,DATE($B$1,1,1)+17*7-1>=$C5),1,"")) | V5: =IF(OR($C5="",$D5=""),"",IF(AND(DATE($B$1,1,1)+(18-1)*7<=$D5,DATE($B$1,1,1)+18*7-1>=$C5),1,"")) | W5: =IF(OR($C5="",$D5=""),"",IF(AND(DATE($B$1,1,1)+(19-1)*7<=$D5,DATE($B$1,1,1)+19*7-1>=$C5),1,"")) | X5: =IF(OR($C5="",$D5=""),"",IF(AND(DATE($B$1,1,1)+(20-1)*7<=$D5,DATE($B$1,1,1)+20*7-1>=$C5),1,"")) | Y5: =IF(OR($C5="",$D5=""),"",IF(AND(DATE($B$1,1,1)+(21-1)*7<=$D5,DATE($B$1,1,1)+21*7-1>=$C5),1,"")) | Z5: =IF(OR($C5="",$D5=""),"",IF(AND(DATE($B$1,1,1)+(22-1)*7<=$D5,DATE($B$1,1,1)+22*7-1>=$C5),1,"")) | AA5: =IF(OR($C5="",$D5=""),"",IF(AND(DATE($B$1,1,1)+(23-1)*7<=$D5,DATE($B$1,1,1)+23*7-1>=$C5),1,"")) | AB5: =IF(OR($C5="",$D5=""),"",IF(AND(DATE($B$1,1,1)+(24-1)*7<=$D5,DATE($B$1,1,1)+24*7-1>=$C5),1,"")) | AC5: =IF(OR($C5="",$D5=""),"",IF(AND(DATE($B$1,1,1)+(25-1)*7<=$D5,DATE($B$1,1,1)+25*7-1>=$C5),1,"")) | AD5: =IF(OR($C5="",$D5=""),"",IF(AND(DATE($B$1,1,1)+(26-1)*7<=$D5,DATE($B$1,1,1)+26*7-1>=$C5),1,"")) | AE5: =IF(OR($C5="",$D5=""),"",IF(AND(DATE($B$1,1,1)+(27-1)*7<=$D5,DATE($B$1,1,1)+27*7-1>=$C5),1,"")) | AF5: =IF(OR($C5="",$D5=""),"",IF(AND(DATE($B$1,1,1)+(28-1)*7<=$D5,DATE($B$1,1,1)+28*7-1>=$C5),1,"")) | AG5: =IF(OR($C5="",$D5=""),"",IF(AND(DATE($B$1,1,1)+(29-1)*7<=$D5,DATE($B$1,1,1)+29*7-1>=$C5),1,"")) | AH5: =IF(OR($C5="",$D5=""),"",IF(AND(DATE($B$1,1,1)+(30-1)*7<=$D5,DATE($B$1,1,1)+30*7-1>=$C5),1,"")) | AI5: =IF(OR($C5="",$D5=""),"",IF(AND(DATE($B$1,1,1)+(31-1)*7<=$D5,DATE($B$1,1,1)+31*7-1>=$C5),1,"")) | AJ5: =IF(OR($C5="",$D5=""),"",IF(AND(DATE($B$1,1,1)+(32-1)*7<=$D5,DATE($B$1,1,1)+32*7-1>=$C5),1,"")) | AK5: =IF(OR($C5="",$D5=""),"",IF(AND(DATE($B$1,1,1)+(33-1)*7<=$D5,DATE($B$1,1,1)+33*7-1>=$C5),1,"")) | AL5: =IF(OR($C5="",$D5=""),"",IF(AND(DATE($B$1,1,1)+(34-1)*7<=$D5,DATE($B$1,1,1)+34*7-1>=$C5),1,"")) | AM5: =IF(OR($C5="",$D5=""),"",IF(AND(DATE($B$1,1,1)+(35-1)*7<=$D5,DATE($B$1,1,1)+35*7-1>=$C5),1,"")) | AN5: =IF(OR($C5="",$D5=""),"",IF(AND(DATE($B$1,1,1)+(36-1)*7<=$D5,DATE($B$1,1,1)+36*7-1>=$C5),1,"")) | AO5: =IF(OR($C5="",$D5=""),"",IF(AND(DATE($B$1,1,1)+(37-1)*7<=$D5,DATE($B$1,1,1)+37*7-1>=$C5),1,"")) | AP5: =IF(OR($C5="",$D5=""),"",IF(AND(DATE($B$1,1,1)+(38-1)*7<=$D5,DATE($B$1,1,1)+38*7-1>=$C5),1,"")) | AQ5: =IF(OR($C5="",$D5=""),"",IF(AND(DATE($B$1,1,1)+(39-1)*7<=$D5,DATE($B$1,1,1)+39*7-1>=$C5),1,"")) | AR5: =IF(OR($C5="",$D5=""),"",IF(AND(DATE($B$1,1,1)+(40-1)*7<=$D5,DATE($B$1,1,1)+40*7-1>=$C5),1,"")) | AS5: =IF(OR($C5="",$D5=""),"",IF(AND(DATE($B$1,1,1)+(41-1)*7<=$D5,DATE($B$1,1,1)+41*7-1>=$C5),1,"")) | AT5: =IF(OR($C5="",$D5=""),"",IF(AND(DATE($B$1,1,1)+(42-1)*7<=$D5,DATE($B$1,1,1)+42*7-1>=$C5),1,"")) | AU5: =IF(OR($C5="",$D5=""),"",IF(AND(DATE($B$1,1,1)+(43-1)*7<=$D5,DATE($B$1,1,1)+43*7-1>=$C5),1,"")) | AV5: =IF(OR($C5="",$D5=""),"",IF(AND(DATE($B$1,1,1)+(44-1)*7<=$D5,DATE($B$1,1,1)+44*7-1>=$C5),1,"")) | AW5: =IF(OR($C5="",$D5=""),"",IF(AND(DATE($B$1,1,1)+(45-1)*7<=$D5,DATE($B$1,1,1)+45*7-1>=$C5),1,"")) | AX5: =IF(OR($C5="",$D5=""),"",IF(AND(DATE($B$1,1,1)+(46-1)*7<=$D5,DATE($B$1,1,1)+46*7-1>=$C5),1,"")) | AY5: =IF(OR($C5="",$D5=""),"",IF(AND(DATE($B$1,1,1)+(47-1)*7<=$D5,DATE($B$1,1,1)+47*7-1>=$C5),1,"")) | AZ5: =IF(OR($C5="",$D5=""),"",IF(AND(DATE($B$1,1,1)+(48-1)*7<=$D5,DATE($B$1,1,1)+48*7-1>=$C5),1,"")) | BA5: =IF(OR($C5="",$D5=""),"",IF(AND(DATE($B$1,1,1)+(49-1)*7<=$D5,DATE($B$1,1,1)+49*7-1>=$C5),1,"")) | BB5: =IF(OR($C5="",$D5=""),"",IF(AND(DATE($B$1,1,1)+(50-1)*7<=$D5,DATE($B$1,1,1)+50*7-1>=$C5),1,"")) | BC5: =IF(OR($C5="",$D5=""),"",IF(AND(DATE($B$1,1,1)+(51-1)*7<=$D5,DATE($B$1,1,1)+51*7-1>=$C5),1,"")) | BD5: =IF(OR($C5="",$D5=""),"",IF(AND(DATE($B$1,1,1)+(52-1)*7<=$D5,DATE($B$1,1,1)+52*7-1>=$C5),1,"")) | BE5: =IF(OR($C5="",$D5=""),"",IF(AND(DATE($B$1,1,1)+(53-1)*7<=$D5,DATE($B$1,1,1)+53*7-1>=$C5),1,"")) | BF5: =IF(OR($C5="",$D5=""),"",IF(AND(DATE($B$1,1,1)+(54-1)*7<=$D5,DATE($B$1,1,1)+54*7-1>=$C5),1,""))
E6: =IF(OR($C6="",$D6=""),"",IF(AND(DATE($B$1,1,1)+(1-1)*7<=$D6,DATE($B$1,1,1)+1*7-1>=$C6),1,"")) | F6: =IF(OR($C6="",$D6=""),"",IF(AND(DATE($B$1,1,1)+(2-1)*7<=$D6,DATE($B$1,1,1)+2*7-1>=$C6),1,"")) | G6: =IF(OR($C6="",$D6=""),"",IF(AND(DATE($B$1,1,1)+(3-1)*7<=$D6,DATE($B$1,1,1)+3*7-1>=$C6),1,"")) | H6: =IF(OR($C6="",$D6=""),"",IF(AND(DATE($B$1,1,1)+(4-1)*7<=$D6,DATE($B$1,1,1)+4*7-1>=$C6),1,"")) | I6: =IF(OR($C6="",$D6=""),"",IF(AND(DATE($B$1,1,1)+(5-1)*7<=$D6,DATE($B$1,1,1)+5*7-1>=$C6),1,"")) | J6: =IF(OR($C6="",$D6=""),"",IF(AND(DATE($B$1,1,1)+(6-1)*7<=$D6,DATE($B$1,1,1)+6*7-1>=$C6),1,"")) | K6: =IF(OR($C6="",$D6=""),"",IF(AND(DATE($B$1,1,1)+(7-1)*7<=$D6,DATE($B$1,1,1)+7*7-1>=$C6),1,"")) | L6: =IF(OR($C6="",$D6=""),"",IF(AND(DATE($B$1,1,1)+(8-1)*7<=$D6,DATE($B$1,1,1)+8*7-1>=$C6),1,"")) | M6: =IF(OR($C6="",$D6=""),"",IF(AND(DATE($B$1,1,1)+(9-1)*7<=$D6,DATE($B$1,1,1)+9*7-1>=$C6),1,"")) | N6: =IF(OR($C6="",$D6=""),"",IF(AND(DATE($B$1,1,1)+(10-1)*7<=$D6,DATE($B$1,1,1)+10*7-1>=$C6),1,"")) | O6: =IF(OR($C6="",$D6=""),"",IF(AND(DATE($B$1,1,1)+(11-1)*7<=$D6,DATE($B$1,1,1)+11*7-1>=$C6),1,"")) | P6: =IF(OR($C6="",$D6=""),"",IF(AND(DATE($B$1,1,1)+(12-1)*7<=$D6,DATE($B$1,1,1)+12*7-1>=$C6),1,"")) | Q6: =IF(OR($C6="",$D6=""),"",IF(AND(DATE($B$1,1,1)+(13-1)*7<=$D6,DATE($B$1,1,1)+13*7-1>=$C6),1,"")) | R6: =IF(OR($C6="",$D6=""),"",IF(AND(DATE($B$1,1,1)+(14-1)*7<=$D6,DATE($B$1,1,1)+14*7-1>=$C6),1,"")) | S6: =IF(OR($C6="",$D6=""),"",IF(AND(DATE($B$1,1,1)+(15-1)*7<=$D6,DATE($B$1,1,1)+15*7-1>=$C6),1,"")) | T6: =IF(OR($C6="",$D6=""),"",IF(AND(DATE($B$1,1,1)+(16-1)*7<=$D6,DATE($B$1,1,1)+16*7-1>=$C6),1,"")) | U6: =IF(OR($C6="",$D6=""),"",IF(AND(DATE($B$1,1,1)+(17-1)*7<=$D6,DATE($B$1,1,1)+17*7-1>=$C6),1,"")) | V6: =IF(OR($C6="",$D6=""),"",IF(AND(DATE($B$1,1,1)+(18-1)*7<=$D6,DATE($B$1,1,1)+18*7-1>=$C6),1,"")) | W6: =IF(OR($C6="",$D6=""),"",IF(AND(DATE($B$1,1,1)+(19-1)*7<=$D6,DATE($B$1,1,1)+19*7-1>=$C6),1,"")) | X6: =IF(OR($C6="",$D6=""),"",IF(AND(DATE($B$1,1,1)+(20-1)*7<=$D6,DATE($B$1,1,1)+20*7-1>=$C6),1,"")) | Y6: =IF(OR($C6="",$D6=""),"",IF(AND(DATE($B$1,1,1)+(21-1)*7<=$D6,DATE($B$1,1,1)+21*7-1>=$C6),1,"")) | Z6: =IF(OR($C6="",$D6=""),"",IF(AND(DATE($B$1,1,1)+(22-1)*7<=$D6,DATE($B$1,1,1)+22*7-1>=$C6),1,"")) | AA6: =IF(OR($C6="",$D6=""),"",IF(AND(DATE($B$1,1,1)+(23-1)*7<=$D6,DATE($B$1,1,1)+23*7-1>=$C6),1,"")) | AB6: =IF(OR($C6="",$D6=""),"",IF(AND(DATE($B$1,1,1)+(24-1)*7<=$D6,DATE($B$1,1,1)+24*7-1>=$C6),1,"")) | AC6: =IF(OR($C6="",$D6=""),"",IF(AND(DATE($B$1,1,1)+(25-1)*7<=$D6,DATE($B$1,1,1)+25*7-1>=$C6),1,"")) | AD6: =IF(OR($C6="",$D6=""),"",IF(AND(DATE($B$1,1,1)+(26-1)*7<=$D6,DATE($B$1,1,1)+26*7-1>=$C6),1,"")) | AE6: =IF(OR($C6="",$D6=""),"",IF(AND(DATE($B$1,1,1)+(27-1)*7<=$D6,DATE($B$1,1,1)+27*7-1>=$C6),1,"")) | AF6: =IF(OR($C6="",$D6=""),"",IF(AND(DATE($B$1,1,1)+(28-1)*7<=$D6,DATE($B$1,1,1)+28*7-1>=$C6),1,"")) | AG6: =IF(OR($C6="",$D6=""),"",IF(AND(DATE($B$1,1,1)+(29-1)*7<=$D6,DATE($B$1,1,1)+29*7-1>=$C6),1,"")) | AH6: =IF(OR($C6="",$D6=""),"",IF(AND(DATE($B$1,1,1)+(30-1)*7<=$D6,DATE($B$1,1,1)+30*7-1>=$C6),1,"")) | AI6: =IF(OR($C6="",$D6=""),"",IF(AND(DATE($B$1,1,1)+(31-1)*7<=$D6,DATE($B$1,1,1)+31*7-1>=$C6),1,"")) | AJ6: =IF(OR($C6="",$D6=""),"",IF(AND(DATE($B$1,1,1)+(32-1)*7<=$D6,DATE($B$1,1,1)+32*7-1>=$C6),1,"")) | AK6: =IF(OR($C6="",$D6=""),"",IF(AND(DATE($B$1,1,1)+(33-1)*7<=$D6,DATE($B$1,1,1)+33*7-1>=$C6),1,"")) | AL6: =IF(OR($C6="",$D6=""),"",IF(AND(DATE($B$1,1,1)+(34-1)*7<=$D6,DATE($B$1,1,1)+34*7-1>=$C6),1,"")) | AM6: =IF(OR($C6="",$D6=""),"",IF(AND(DATE($B$1,1,1)+(35-1)*7<=$D6,DATE($B$1,1,1)+35*7-1>=$C6),1,"")) | AN6: =IF(OR($C6="",$D6=""),"",IF(AND(DATE($B$1,1,1)+(36-1)*7<=$D6,DATE($B$1,1,1)+36*7-1>=$C6),1,"")) | AO6: =IF(OR($C6="",$D6=""),"",IF(AND(DATE($B$1,1,1)+(37-1)*7<=$D6,DATE($B$1,1,1)+37*7-1>=$C6),1,"")) | AP6: =IF(OR($C6="",$D6=""),"",IF(AND(DATE($B$1,1,1)+(38-1)*7<=$D6,DATE($B$1,1,1)+38*7-1>=$C6),1,"")) | AQ6: =IF(OR($C6="",$D6=""),"",IF(AND(DATE($B$1,1,1)+(39-1)*7<=$D6,DATE($B$1,1,1)+39*7-1>=$C6),1,"")) | AR6: =IF(OR($C6="",$D6=""),"",IF(AND(DATE($B$1,1,1)+(40-1)*7<=$D6,DATE($B$1,1,1)+40*7-1>=$C6),1,"")) | AS6: =IF(OR($C6="",$D6=""),"",IF(AND(DATE($B$1,1,1)+(41-1)*7<=$D6,DATE($B$1,1,1)+41*7-1>=$C6),1,"")) | AT6: =IF(OR($C6="",$D6=""),"",IF(AND(DATE($B$1,1,1)+(42-1)*7<=$D6,DATE($B$1,1,1)+42*7-1>=$C6),1,"")) | AU6: =IF(OR($C6="",$D6=""),"",IF(AND(DATE($B$1,1,1)+(43-1)*7<=$D6,DATE($B$1,1,1)+43*7-1>=$C6),1,"")) | AV6: =IF(OR($C6="",$D6=""),"",IF(AND(DATE($B$1,1,1)+(44-1)*7<=$D6,DATE($B$1,1,1)+44*7-1>=$C6),1,"")) | AW6: =IF(OR($C6="",$D6=""),"",IF(AND(DATE($B$1,1,1)+(45-1)*7<=$D6,DATE($B$1,1,1)+45*7-1>=$C6),1,"")) | AX6: =IF(OR($C6="",$D6=""),"",IF(AND(DATE($B$1,1,1)+(46-1)*7<=$D6,DATE($B$1,1,1)+46*7-1>=$C6),1,"")) | AY6: =IF(OR($C6="",$D6=""),"",IF(AND(DATE($B$1,1,1)+(47-1)*7<=$D6,DATE($B$1,1,1)+47*7-1>=$C6),1,"")) | AZ6: =IF(OR($C6="",$D6=""),"",IF(AND(DATE($B$1,1,1)+(48-1)*7<=$D6,DATE($B$1,1,1)+48*7-1>=$C6),1,"")) | BA6: =IF(OR($C6="",$D6=""),"",IF(AND(DATE($B$1,1,1)+(49-1)*7<=$D6,DATE($B$1,1,1)+49*7-1>=$C6),1,"")) | BB6: =IF(OR($C6="",$D6=""),"",IF(AND(DATE($B$1,1,1)+(50-1)*7<=$D6,DATE($B$1,1,1)+50*7-1>=$C6),1,"")) | BC6: =IF(OR($C6="",$D6=""),"",IF(AND(DATE($B$1,1,1)+(51-1)*7<=$D6,DATE($B$1,1,1)+51*7-1>=$C6),1,"")) | BD6: =IF(OR($C6="",$D6=""),"",IF(AND(DATE($B$1,1,1)+(52-1)*7<=$D6,DATE($B$1,1,1)+52*7-1>=$C6),1,"")) | BE6: =IF(OR($C6="",$D6=""),"",IF(AND(DATE($B$1,1,1)+(53-1)*7<=$D6,DATE($B$1,1,1)+53*7-1>=$C6),1,"")) | BF6: =IF(OR($C6="",$D6=""),"",IF(AND(DATE($B$1,1,1)+(54-1)*7<=$D6,DATE($B$1,1,1)+54*7-1>=$C6),1,""))
E7: =IF(OR($C7="",$D7=""),"",IF(AND(DATE($B$1,1,1)+(1-1)*7<=$D7,DATE($B$1,1,1)+1*7-1>=$C7),1,"")) | F7: =IF(OR($C7="",$D7=""),"",IF(AND(DATE($B$1,1,1)+(2-1)*7<=$D7,DATE($B$1,1,1)+2*7-1>=$C7),1,"")) | G7: =IF(OR($C7="",$D7=""),"",IF(AND(DATE($B$1,1,1)+(3-1)*7<=$D7,DATE($B$1,1,1)+3*7-1>=$C7),1,"")) | H7: =IF(OR($C7="",$D7=""),"",IF(AND(DATE($B$1,1,1)+(4-1)*7<=$D7,DATE($B$1,1,1)+4*7-1>=$C7),1,"")) | I7: =IF(OR($C7="",$D7=""),"",IF(AND(DATE($B$1,1,1)+(5-1)*7<=$D7,DATE($B$1,1,1)+5*7-1>=$C7),1,"")) | J7: =IF(OR($C7="",$D7=""),"",IF(AND(DATE($B$1,1,1)+(6-1)*7<=$D7,DATE($B$1,1,1)+6*7-1>=$C7),1,"")) | K7: =IF(OR($C7="",$D7=""),"",IF(AND(DATE($B$1,1,1)+(7-1)*7<=$D7,DATE($B$1,1,1)+7*7-1>=$C7),1,"")) | L7: =IF(OR($C7="",$D7=""),"",IF(AND(DATE($B$1,1,1)+(8-1)*7<=$D7,DATE($B$1,1,1)+8*7-1>=$C7),1,"")) | M7: =IF(OR($C7="",$D7=""),"",IF(AND(DATE($B$1,1,1)+(9-1)*7<=$D7,DATE($B$1,1,1)+9*7-1>=$C7),1,"")) | N7: =IF(OR($C7="",$D7=""),"",IF(AND(DATE($B$1,1,1)+(10-1)*7<=$D7,DATE($B$1,1,1)+10*7-1>=$C7),1,"")) | O7: =IF(OR($C7="",$D7=""),"",IF(AND(DATE($B$1,1,1)+(11-1)*7<=$D7,DATE($B$1,1,1)+11*7-1>=$C7),1,"")) | P7: =IF(OR($C7="",$D7=""),"",IF(AND(DATE($B$1,1,1)+(12-1)*7<=$D7,DATE($B$1,1,1)+12*7-1>=$C7),1,"")) | Q7: =IF(OR($C7="",$D7=""),"",IF(AND(DATE($B$1,1,1)+(13-1)*7<=$D7,DATE($B$1,1,1)+13*7-1>=$C7),1,"")) | R7: =IF(OR($C7="",$D7=""),"",IF(AND(DATE($B$1,1,1)+(14-1)*7<=$D7,DATE($B$1,1,1)+14*7-1>=$C7),1,"")) | S7: =IF(OR($C7="",$D7=""),"",IF(AND(DATE($B$1,1,1)+(15-1)*7<=$D7,DATE($B$1,1,1)+15*7-1>=$C7),1,"")) | T7: =IF(OR($C7="",$D7=""),"",IF(AND(DATE($B$1,1,1)+(16-1)*7<=$D7,DATE($B$1,1,1)+16*7-1>=$C7),1,"")) | U7: =IF(OR($C7="",$D7=""),"",IF(AND(DATE($B$1,1,1)+(17-1)*7<=$D7,DATE($B$1,1,1)+17*7-1>=$C7),1,"")) | V7: =IF(OR($C7="",$D7=""),"",IF(AND(DATE($B$1,1,1)+(18-1)*7<=$D7,DATE($B$1,1,1)+18*7-1>=$C7),1,"")) | W7: =IF(OR($C7="",$D7=""),"",IF(AND(DATE($B$1,1,1)+(19-1)*7<=$D7,DATE($B$1,1,1)+19*7-1>=$C7),1,"")) | X7: =IF(OR($C7="",$D7=""),"",IF(AND(DATE($B$1,1,1)+(20-1)*7<=$D7,DATE($B$1,1,1)+20*7-1>=$C7),1,"")) | Y7: =IF(OR($C7="",$D7=""),"",IF(AND(DATE($B$1,1,1)+(21-1)*7<=$D7,DATE($B$1,1,1)+21*7-1>=$C7),1,"")) | Z7: =IF(OR($C7="",$D7=""),"",IF(AND(DATE($B$1,1,1)+(22-1)*7<=$D7,DATE($B$1,1,1)+22*7-1>=$C7),1,"")) | AA7: =IF(OR($C7="",$D7=""),"",IF(AND(DATE($B$1,1,1)+(23-1)*7<=$D7,DATE($B$1,1,1)+23*7-1>=$C7),1,"")) | AB7: =IF(OR($C7="",$D7=""),"",IF(AND(DATE($B$1,1,1)+(24-1)*7<=$D7,DATE($B$1,1,1)+24*7-1>=$C7),1,"")) | AC7: =IF(OR($C7="",$D7=""),"",IF(AND(DATE($B$1,1,1)+(25-1)*7<=$D7,DATE($B$1,1,1)+25*7-1>=$C7),1,"")) | AD7: =IF(OR($C7="",$D7=""),"",IF(AND(DATE($B$1,1,1)+(26-1)*7<=$D7,DATE($B$1,1,1)+26*7-1>=$C7),1,"")) | AE7: =IF(OR($C7="",$D7=""),"",IF(AND(DATE($B$1,1,1)+(27-1)*7<=$D7,DATE($B$1,1,1)+27*7-1>=$C7),1,"")) | AF7: =IF(OR($C7="",$D7=""),"",IF(AND(DATE($B$1,1,1)+(28-1)*7<=$D7,DATE($B$1,1,1)+28*7-1>=$C7),1,"")) | AG7: =IF(OR($C7="",$D7=""),"",IF(AND(DATE($B$1,1,1)+(29-1)*7<=$D7,DATE($B$1,1,1)+29*7-1>=$C7),1,"")) | AH7: =IF(OR($C7="",$D7=""),"",IF(AND(DATE($B$1,1,1)+(30-1)*7<=$D7,DATE($B$1,1,1)+30*7-1>=$C7),1,"")) | AI7: =IF(OR($C7="",$D7=""),"",IF(AND(DATE($B$1,1,1)+(31-1)*7<=$D7,DATE($B$1,1,1)+31*7-1>=$C7),1,"")) | AJ7: =IF(OR($C7="",$D7=""),"",IF(AND(DATE($B$1,1,1)+(32-1)*7<=$D7,DATE($B$1,1,1)+32*7-1>=$C7),1,"")) | AK7: =IF(OR($C7="",$D7=""),"",IF(AND(DATE($B$1,1,1)+(33-1)*7<=$D7,DATE($B$1,1,1)+33*7-1>=$C7),1,"")) | AL7: =IF(OR($C7="",$D7=""),"",IF(AND(DATE($B$1,1,1)+(34-1)*7<=$D7,DATE($B$1,1,1)+34*7-1>=$C7),1,"")) | AM7: =IF(OR($C7="",$D7=""),"",IF(AND(DATE($B$1,1,1)+(35-1)*7<=$D7,DATE($B$1,1,1)+35*7-1>=$C7),1,"")) | AN7: =IF(OR($C7="",$D7=""),"",IF(AND(DATE($B$1,1,1)+(36-1)*7<=$D7,DATE($B$1,1,1)+36*7-1>=$C7),1,"")) | AO7: =IF(OR($C7="",$D7=""),"",IF(AND(DATE($B$1,1,1)+(37-1)*7<=$D7,DATE($B$1,1,1)+37*7-1>=$C7),1,"")) | AP7: =IF(OR($C7="",$D7=""),"",IF(AND(DATE($B$1,1,1)+(38-1)*7<=$D7,DATE($B$1,1,1)+38*7-1>=$C7),1,"")) | AQ7: =IF(OR($C7="",$D7=""),"",IF(AND(DATE($B$1,1,1)+(39-1)*7<=$D7,DATE($B$1,1,1)+39*7-1>=$C7),1,"")) | AR7: =IF(OR($C7="",$D7=""),"",IF(AND(DATE($B$1,1,1)+(40-1)*7<=$D7,DATE($B$1,1,1)+40*7-1>=$C7),1,"")) | AS7: =IF(OR($C7="",$D7=""),"",IF(AND(DATE($B$1,1,1)+(41-1)*7<=$D7,DATE($B$1,1,1)+41*7-1>=$C7),1,"")) | AT7: =IF(OR($C7="",$D7=""),"",IF(AND(DATE($B$1,1,1)+(42-1)*7<=$D7,DATE($B$1,1,1)+42*7-1>=$C7),1,"")) | AU7: =IF(OR($C7="",$D7=""),"",IF(AND(DATE($B$1,1,1)+(43-1)*7<=$D7,DATE($B$1,1,1)+43*7-1>=$C7),1,"")) | AV7: =IF(OR($C7="",$D7=""),"",IF(AND(DATE($B$1,1,1)+(44-1)*7<=$D7,DATE($B$1,1,1)+44*7-1>=$C7),1,"")) | AW7: =IF(OR($C7="",$D7=""),"",IF(AND(DATE($B$1,1,1)+(45-1)*7<=$D7,DATE($B$1,1,1)+45*7-1>=$C7),1,"")) | AX7: =IF(OR($C7="",$D7=""),"",IF(AND(DATE($B$1,1,1)+(46-1)*7<=$D7,DATE($B$1,1,1)+46*7-1>=$C7),1,"")) | AY7: =IF(OR($C7="",$D7=""),"",IF(AND(DATE($B$1,1,1)+(47-1)*7<=$D7,DATE($B$1,1,1)+47*7-1>=$C7),1,"")) | AZ7: =IF(OR($C7="",$D7=""),"",IF(AND(DATE($B$1,1,1)+(48-1)*7<=$D7,DATE($B$1,1,1)+48*7-1>=$C7),1,"")) | BA7: =IF(OR($C7="",$D7=""),"",IF(AND(DATE($B$1,1,1)+(49-1)*7<=$D7,DATE($B$1,1,1)+49*7-1>=$C7),1,"")) | BB7: =IF(OR($C7="",$D7=""),"",IF(AND(DATE($B$1,1,1)+(50-1)*7<=$D7,DATE($B$1,1,1)+50*7-1>=$C7),1,"")) | BC7: =IF(OR($C7="",$D7=""),"",IF(AND(DATE($B$1,1,1)+(51-1)*7<=$D7,DATE($B$1,1,1)+51*7-1>=$C7),1,"")) | BD7: =IF(OR($C7="",$D7=""),"",IF(AND(DATE($B$1,1,1)+(52-1)*7<=$D7,DATE($B$1,1,1)+52*7-1>=$C7),1,"")) | BE7: =IF(OR($C7="",$D7=""),"",IF(AND(DATE($B$1,1,1)+(53-1)*7<=$D7,DATE($B$1,1,1)+53*7-1>=$C7),1,"")) | BF7: =IF(OR($C7="",$D7=""),"",IF(AND(DATE($B$1,1,1)+(54-1)*7<=$D7,DATE($B$1,1,1)+54*7-1>=$C7),1,""))
E8: =IF(OR($C8="",$D8=""),"",IF(AND(DATE($B$1,1,1)+(1-1)*7<=$D8,DATE($B$1,1,1)+1*7-1>=$C8),1,"")) | F8: =IF(OR($C8="",$D8=""),"",IF(AND(DATE($B$1,1,1)+(2-1)*7<=$D8,DATE($B$1,1,1)+2*7-1>=$C8),1,"")) | G8: =IF(OR($C8="",$D8=""),"",IF(AND(DATE($B$1,1,1)+(3-1)*7<=$D8,DATE($B$1,1,1)+3*7-1>=$C8),1,"")) | H8: =IF(OR($C8="",$D8=""),"",IF(AND(DATE($B$1,1,1)+(4-1)*7<=$D8,DATE($B$1,1,1)+4*7-1>=$C8),1,"")) | I8: =IF(OR($C8="",$D8=""),"",IF(AND(DATE($B$1,1,1)+(5-1)*7<=$D8,DATE($B$1,1,1)+5*7-1>=$C8),1,"")) | J8: =IF(OR($C8="",$D8=""),"",IF(AND(DATE($B$1,1,1)+(6-1)*7<=$D8,DATE($B$1,1,1)+6*7-1>=$C8),1,"")) | K8: =IF(OR($C8="",$D8=""),"",IF(AND(DATE($B$1,1,1)+(7-1)*7<=$D8,DATE($B$1,1,1)+7*7-1>=$C8),1,"")) | L8: =IF(OR($C8="",$D8=""),"",IF(AND(DATE($B$1,1,1)+(8-1)*7<=$D8,DATE($B$1,1,1)+8*7-1>=$C8),1,"")) | M8: =IF(OR($C8="",$D8=""),"",IF(AND(DATE($B$1,1,1)+(9-1)*7<=$D8,DATE($B$1,1,1)+9*7-1>=$C8),1,"")) | N8: =IF(OR($C8="",$D8=""),"",IF(AND(DATE($B$1,1,1)+(10-1)*7<=$D8,DATE($B$1,1,1)+10*7-1>=$C8),1,"")) | O8: =IF(OR($C8="",$D8=""),"",IF(AND(DATE($B$1,1,1)+(11-1)*7<=$D8,DATE($B$1,1,1)+11*7-1>=$C8),1,"")) | P8: =IF(OR($C8="",$D8=""),"",IF(AND(DATE($B$1,1,1)+(12-1)*7<=$D8,DATE($B$1,1,1)+12*7-1>=$C8),1,"")) | Q8: =IF(OR($C8="",$D8=""),"",IF(AND(DATE($B$1,1,1)+(13-1)*7<=$D8,DATE($B$1,1,1)+13*7-1>=$C8),1,"")) | R8: =IF(OR($C8="",$D8=""),"",IF(AND(DATE($B$1,1,1)+(14-1)*7<=$D8,DATE($B$1,1,1)+14*7-1>=$C8),1,"")) | S8: =IF(OR($C8="",$D8=""),"",IF(AND(DATE($B$1,1,1)+(15-1)*7<=$D8,DATE($B$1,1,1)+15*7-1>=$C8),1,"")) | T8: =IF(OR($C8="",$D8=""),"",IF(AND(DATE($B$1,1,1)+(16-1)*7<=$D8,DATE($B$1,1,1)+16*7-1>=$C8),1,"")) | U8: =IF(OR($C8="",$D8=""),"",IF(AND(DATE($B$1,1,1)+(17-1)*7<=$D8,DATE($B$1,1,1)+17*7-1>=$C8),1,"")) | V8: =IF(OR($C8="",$D8=""),"",IF(AND(DATE($B$1,1,1)+(18-1)*7<=$D8,DATE($B$1,1,1)+18*7-1>=$C8),1,"")) | W8: =IF(OR($C8="",$D8=""),"",IF(AND(DATE($B$1,1,1)+(19-1)*7<=$D8,DATE($B$1,1,1)+19*7-1>=$C8),1,"")) | X8: =IF(OR($C8="",$D8=""),"",IF(AND(DATE($B$1,1,1)+(20-1)*7<=$D8,DATE($B$1,1,1)+20*7-1>=$C8),1,"")) | Y8: =IF(OR($C8="",$D8=""),"",IF(AND(DATE($B$1,1,1)+(21-1)*7<=$D8,DATE($B$1,1,1)+21*7-1>=$C8),1,"")) | Z8: =IF(OR($C8="",$D8=""),"",IF(AND(DATE($B$1,1,1)+(22-1)*7<=$D8,DATE($B$1,1,1)+22*7-1>=$C8),1,"")) | AA8: =IF(OR($C8="",$D8=""),"",IF(AND(DATE($B$1,1,1)+(23-1)*7<=$D8,DATE($B$1,1,1)+23*7-1>=$C8),1,"")) | AB8: =IF(OR($C8="",$D8=""),"",IF(AND(DATE($B$1,1,1)+(24-1)*7<=$D8,DATE($B$1,1,1)+24*7-1>=$C8),1,"")) | AC8: =IF(OR($C8="",$D8=""),"",IF(AND(DATE($B$1,1,1)+(25-1)*7<=$D8,DATE($B$1,1,1)+25*7-1>=$C8),1,"")) | AD8: =IF(OR($C8="",$D8=""),"",IF(AND(DATE($B$1,1,1)+(26-1)*7<=$D8,DATE($B$1,1,1)+26*7-1>=$C8),1,"")) | AE8: =IF(OR($C8="",$D8=""),"",IF(AND(DATE($B$1,1,1)+(27-1)*7<=$D8,DATE($B$1,1,1)+27*7-1>=$C8),1,"")) | AF8: =IF(OR($C8="",$D8=""),"",IF(AND(DATE($B$1,1,1)+(28-1)*7<=$D8,DATE($B$1,1,1)+28*7-1>=$C8),1,"")) | AG8: =IF(OR($C8="",$D8=""),"",IF(AND(DATE($B$1,1,1)+(29-1)*7<=$D8,DATE($B$1,1,1)+29*7-1>=$C8),1,"")) | AH8: =IF(OR($C8="",$D8=""),"",IF(AND(DATE($B$1,1,1)+(30-1)*7<=$D8,DATE($B$1,1,1)+30*7-1>=$C8),1,"")) | AI8: =IF(OR($C8="",$D8=""),"",IF(AND(DATE($B$1,1,1)+(31-1)*7<=$D8,DATE($B$1,1,1)+31*7-1>=$C8),1,"")) | AJ8: =IF(OR($C8="",$D8=""),"",IF(AND(DATE($B$1,1,1)+(32-1)*7<=$D8,DATE($B$1,1,1)+32*7-1>=$C8),1,"")) | AK8: =IF(OR($C8="",$D8=""),"",IF(AND(DATE($B$1,1,1)+(33-1)*7<=$D8,DATE($B$1,1,1)+33*7-1>=$C8),1,"")) | AL8: =IF(OR($C8="",$D8=""),"",IF(AND(DATE($B$1,1,1)+(34-1)*7<=$D8,DATE($B$1,1,1)+34*7-1>=$C8),1,"")) | AM8: =IF(OR($C8="",$D8=""),"",IF(AND(DATE($B$1,1,1)+(35-1)*7<=$D8,DATE($B$1,1,1)+35*7-1>=$C8),1,"")) | AN8: =IF(OR($C8="",$D8=""),"",IF(AND(DATE($B$1,1,1)+(36-1)*7<=$D8,DATE($B$1,1,1)+36*7-1>=$C8),1,"")) | AO8: =IF(OR($C8="",$D8=""),"",IF(AND(DATE($B$1,1,1)+(37-1)*7<=$D8,DATE($B$1,1,1)+37*7-1>=$C8),1,"")) | AP8: =IF(OR($C8="",$D8=""),"",IF(AND(DATE($B$1,1,1)+(38-1)*7<=$D8,DATE($B$1,1,1)+38*7-1>=$C8),1,"")) | AQ8: =IF(OR($C8="",$D8=""),"",IF(AND(DATE($B$1,1,1)+(39-1)*7<=$D8,DATE($B$1,1,1)+39*7-1>=$C8),1,"")) | AR8: =IF(OR($C8="",$D8=""),"",IF(AND(DATE($B$1,1,1)+(40-1)*7<=$D8,DATE($B$1,1,1)+40*7-1>=$C8),1,"")) | AS8: =IF(OR($C8="",$D8=""),"",IF(AND(DATE($B$1,1,1)+(41-1)*7<=$D8,DATE($B$1,1,1)+41*7-1>=$C8),1,"")) | AT8: =IF(OR($C8="",$D8=""),"",IF(AND(DATE($B$1,1,1)+(42-1)*7<=$D8,DATE($B$1,1,1)+42*7-1>=$C8),1,"")) | AU8: =IF(OR($C8="",$D8=""),"",IF(AND(DATE($B$1,1,1)+(43-1)*7<=$D8,DATE($B$1,1,1)+43*7-1>=$C8),1,"")) | AV8: =IF(OR($C8="",$D8=""),"",IF(AND(DATE($B$1,1,1)+(44-1)*7<=$D8,DATE($B$1,1,1)+44*7-1>=$C8),1,"")) | AW8: =IF(OR($C8="",$D8=""),"",IF(AND(DATE($B$1,1,1)+(45-1)*7<=$D8,DATE($B$1,1,1)+45*7-1>=$C8),1,"")) | AX8: =IF(OR($C8="",$D8=""),"",IF(AND(DATE($B$1,1,1)+(46-1)*7<=$D8,DATE($B$1,1,1)+46*7-1>=$C8),1,"")) | AY8: =IF(OR($C8="",$D8=""),"",IF(AND(DATE($B$1,1,1)+(47-1)*7<=$D8,DATE($B$1,1,1)+47*7-1>=$C8),1,"")) | AZ8: =IF(OR($C8="",$D8=""),"",IF(AND(DATE($B$1,1,1)+(48-1)*7<=$D8,DATE($B$1,1,1)+48*7-1>=$C8),1,"")) | BA8: =IF(OR($C8="",$D8=""),"",IF(AND(DATE($B$1,1,1)+(49-1)*7<=$D8,DATE($B$1,1,1)+49*7-1>=$C8),1,"")) | BB8: =IF(OR($C8="",$D8=""),"",IF(AND(DATE($B$1,1,1)+(50-1)*7<=$D8,DATE($B$1,1,1)+50*7-1>=$C8),1,"")) | BC8: =IF(OR($C8="",$D8=""),"",IF(AND(DATE($B$1,1,1)+(51-1)*7<=$D8,DATE($B$1,1,1)+51*7-1>=$C8),1,"")) | BD8: =IF(OR($C8="",$D8=""),"",IF(AND(DATE($B$1,1,1)+(52-1)*7<=$D8,DATE($B$1,1,1)+52*7-1>=$C8),1,"")) | BE8: =IF(OR($C8="",$D8=""),"",IF(AND(DATE($B$1,1,1)+(53-1)*7<=$D8,DATE($B$1,1,1)+53*7-1>=$C8),1,"")) | BF8: =IF(OR($C8="",$D8=""),"",IF(AND(DATE($B$1,1,1)+(54-1)*7<=$D8,DATE($B$1,1,1)+54*7-1>=$C8),1,""))
E9: =IF(OR($C9="",$D9=""),"",IF(AND(DATE($B$1,1,1)+(1-1)*7<=$D9,DATE($B$1,1,1)+1*7-1>=$C9),1,"")) | F9: =IF(OR($C9="",$D9=""),"",IF(AND(DATE($B$1,1,1)+(2-1)*7<=$D9,DATE($B$1,1,1)+2*7-1>=$C9),1,"")) | G9: =IF(OR($C9="",$D9=""),"",IF(AND(DATE($B$1,1,1)+(3-1)*7<=$D9,DATE($B$1,1,1)+3*7-1>=$C9),1,"")) | H9: =IF(OR($C9="",$D9=""),"",IF(AND(DATE($B$1,1,1)+(4-1)*7<=$D9,DATE($B$1,1,1)+4*7-1>=$C9),1,"")) | I9: =IF(OR($C9="",$D9=""),"",IF(AND(DATE($B$1,1,1)+(5-1)*7<=$D9,DATE($B$1,1,1)+5*7-1>=$C9),1,"")) | J9: =IF(OR($C9="",$D9=""),"",IF(AND(DATE($B$1,1,1)+(6-1)*7<=$D9,DATE($B$1,1,1)+6*7-1>=$C9),1,"")) | K9: =IF(OR($C9="",$D9=""),"",IF(AND(DATE($B$1,1,1)+(7-1)*7<=$D9,DATE($B$1,1,1)+7*7-1>=$C9),1,"")) | L9: =IF(OR($C9="",$D9=""),"",IF(AND(DATE($B$1,1,1)+(8-1)*7<=$D9,DATE($B$1,1,1)+8*7-1>=$C9),1,"")) | M9: =IF(OR($C9="",$D9=""),"",IF(AND(DATE($B$1,1,1)+(9-1)*7<=$D9,DATE($B$1,1,1)+9*7-1>=$C9),1,"")) | N9: =IF(OR($C9="",$D9=""),"",IF(AND(DATE($B$1,1,1)+(10-1)*7<=$D9,DATE($B$1,1,1)+10*7-1>=$C9),1,"")) | O9: =IF(OR($C9="",$D9=""),"",IF(AND(DATE($B$1,1,1)+(11-1)*7<=$D9,DATE($B$1,1,1)+11*7-1>=$C9),1,"")) | P9: =IF(OR($C9="",$D9=""),"",IF(AND(DATE($B$1,1,1)+(12-1)*7<=$D9,DATE($B$1,1,1)+12*7-1>=$C9),1,"")) | Q9: =IF(OR($C9="",$D9=""),"",IF(AND(DATE($B$1,1,1)+(13-1)*7<=$D9,DATE($B$1,1,1)+13*7-1>=$C9),1,"")) | R9: =IF(OR($C9="",$D9=""),"",IF(AND(DATE($B$1,1,1)+(14-1)*7<=$D9,DATE($B$1,1,1)+14*7-1>=$C9),1,"")) | S9: =IF(OR($C9="",$D9=""),"",IF(AND(DATE($B$1,1,1)+(15-1)*7<=$D9,DATE($B$1,1,1)+15*7-1>=$C9),1,"")) | T9: =IF(OR($C9="",$D9=""),"",IF(AND(DATE($B$1,1,1)+(16-1)*7<=$D9,DATE($B$1,1,1)+16*7-1>=$C9),1,"")) | U9: =IF(OR($C9="",$D9=""),"",IF(AND(DATE($B$1,1,1)+(17-1)*7<=$D9,DATE($B$1,1,1)+17*7-1>=$C9),1,"")) | V9: =IF(OR($C9="",$D9=""),"",IF(AND(DATE($B$1,1,1)+(18-1)*7<=$D9,DATE($B$1,1,1)+18*7-1>=$C9),1,"")) | W9: =IF(OR($C9="",$D9=""),"",IF(AND(DATE($B$1,1,1)+(19-1)*7<=$D9,DATE($B$1,1,1)+19*7-1>=$C9),1,"")) | X9: =IF(OR($C9="",$D9=""),"",IF(AND(DATE($B$1,1,1)+(20-1)*7<=$D9,DATE($B$1,1,1)+20*7-1>=$C9),1,"")) | Y9: =IF(OR($C9="",$D9=""),"",IF(AND(DATE($B$1,1,1)+(21-1)*7<=$D9,DATE($B$1,1,1)+21*7-1>=$C9),1,"")) | Z9: =IF(OR($C9="",$D9=""),"",IF(AND(DATE($B$1,1,1)+(22-1)*7<=$D9,DATE($B$1,1,1)+22*7-1>=$C9),1,"")) | AA9: =IF(OR($C9="",$D9=""),"",IF(AND(DATE($B$1,1,1)+(23-1)*7<=$D9,DATE($B$1,1,1)+23*7-1>=$C9),1,"")) | AB9: =IF(OR($C9="",$D9=""),"",IF(AND(DATE($B$1,1,1)+(24-1)*7<=$D9,DATE($B$1,1,1)+24*7-1>=$C9),1,"")) | AC9: =IF(OR($C9="",$D9=""),"",IF(AND(DATE($B$1,1,1)+(25-1)*7<=$D9,DATE($B$1,1,1)+25*7-1>=$C9),1,"")) | AD9: =IF(OR($C9="",$D9=""),"",IF(AND(DATE($B$1,1,1)+(26-1)*7<=$D9,DATE($B$1,1,1)+26*7-1>=$C9),1,"")) | AE9: =IF(OR($C9="",$D9=""),"",IF(AND(DATE($B$1,1,1)+(27-1)*7<=$D9,DATE($B$1,1,1)+27*7-1>=$C9),1,"")) | AF9: =IF(OR($C9="",$D9=""),"",IF(AND(DATE($B$1,1,1)+(28-1)*7<=$D9,DATE($B$1,1,1)+28*7-1>=$C9),1,"")) | AG9: =IF(OR($C9="",$D9=""),"",IF(AND(DATE($B$1,1,1)+(29-1)*7<=$D9,DATE($B$1,1,1)+29*7-1>=$C9),1,"")) | AH9: =IF(OR($C9="",$D9=""),"",IF(AND(DATE($B$1,1,1)+(30-1)*7<=$D9,DATE($B$1,1,1)+30*7-1>=$C9),1,"")) | AI9: =IF(OR($C9="",$D9=""),"",IF(AND(DATE($B$1,1,1)+(31-1)*7<=$D9,DATE($B$1,1,1)+31*7-1>=$C9),1,"")) | AJ9: =IF(OR($C9="",$D9=""),"",IF(AND(DATE($B$1,1,1)+(32-1)*7<=$D9,DATE($B$1,1,1)+32*7-1>=$C9),1,"")) | AK9: =IF(OR($C9="",$D9=""),"",IF(AND(DATE($B$1,1,1)+(33-1)*7<=$D9,DATE($B$1,1,1)+33*7-1>=$C9),1,"")) | AL9: =IF(OR($C9="",$D9=""),"",IF(AND(DATE($B$1,1,1)+(34-1)*7<=$D9,DATE($B$1,1,1)+34*7-1>=$C9),1,"")) | AM9: =IF(OR($C9="",$D9=""),"",IF(AND(DATE($B$1,1,1)+(35-1)*7<=$D9,DATE($B$1,1,1)+35*7-1>=$C9),1,"")) | AN9: =IF(OR($C9="",$D9=""),"",IF(AND(DATE($B$1,1,1)+(36-1)*7<=$D9,DATE($B$1,1,1)+36*7-1>=$C9),1,"")) | AO9: =IF(OR($C9="",$D9=""),"",IF(AND(DATE($B$1,1,1)+(37-1)*7<=$D9,DATE($B$1,1,1)+37*7-1>=$C9),1,"")) | AP9: =IF(OR($C9="",$D9=""),"",IF(AND(DATE($B$1,1,1)+(38-1)*7<=$D9,DATE($B$1,1,1)+38*7-1>=$C9),1,"")) | AQ9: =IF(OR($C9="",$D9=""),"",IF(AND(DATE($B$1,1,1)+(39-1)*7<=$D9,DATE($B$1,1,1)+39*7-1>=$C9),1,"")) | AR9: =IF(OR($C9="",$D9=""),"",IF(AND(DATE($B$1,1,1)+(40-1)*7<=$D9,DATE($B$1,1,1)+40*7-1>=$C9),1,"")) | AS9: =IF(OR($C9="",$D9=""),"",IF(AND(DATE($B$1,1,1)+(41-1)*7<=$D9,DATE($B$1,1,1)+41*7-1>=$C9),1,"")) | AT9: =IF(OR($C9="",$D9=""),"",IF(AND(DATE($B$1,1,1)+(42-1)*7<=$D9,DATE($B$1,1,1)+42*7-1>=$C9),1,"")) | AU9: =IF(OR($C9="",$D9=""),"",IF(AND(DATE($B$1,1,1)+(43-1)*7<=$D9,DATE($B$1,1,1)+43*7-1>=$C9),1,"")) | AV9: =IF(OR($C9="",$D9=""),"",IF(AND(DATE($B$1,1,1)+(44-1)*7<=$D9,DATE($B$1,1,1)+44*7-1>=$C9),1,"")) | AW9: =IF(OR($C9="",$D9=""),"",IF(AND(DATE($B$1,1,1)+(45-1)*7<=$D9,DATE($B$1,1,1)+45*7-1>=$C9),1,"")) | AX9: =IF(OR($C9="",$D9=""),"",IF(AND(DATE($B$1,1,1)+(46-1)*7<=$D9,DATE($B$1,1,1)+46*7-1>=$C9),1,"")) | AY9: =IF(OR($C9="",$D9=""),"",IF(AND(DATE($B$1,1,1)+(47-1)*7<=$D9,DATE($B$1,1,1)+47*7-1>=$C9),1,"")) | AZ9: =IF(OR($C9="",$D9=""),"",IF(AND(DATE($B$1,1,1)+(48-1)*7<=$D9,DATE($B$1,1,1)+48*7-1>=$C9),1,"")) | BA9: =IF(OR($C9="",$D9=""),"",IF(AND(DATE($B$1,1,1)+(49-1)*7<=$D9,DATE($B$1,1,1)+49*7-1>=$C9),1,"")) | BB9: =IF(OR($C9="",$D9=""),"",IF(AND(DATE($B$1,1,1)+(50-1)*7<=$D9,DATE($B$1,1,1)+50*7-1>=$C9),1,"")) | BC9: =IF(OR($C9="",$D9=""),"",IF(AND(DATE($B$1,1,1)+(51-1)*7<=$D9,DATE($B$1,1,1)+51*7-1>=$C9),1,"")) | BD9: =IF(OR($C9="",$D9=""),"",IF(AND(DATE($B$1,1,1)+(52-1)*7<=$D9,DATE($B$1,1,1)+52*7-1>=$C9),1,"")) | BE9: =IF(OR($C9="",$D9=""),"",IF(AND(DATE($B$1,1,1)+(53-1)*7<=$D9,DATE($B$1,1,1)+53*7-1>=$C9),1,"")) | BF9: =IF(OR($C9="",$D9=""),"",IF(AND(DATE($B$1,1,1)+(54-1)*7<=$D9,DATE($B$1,1,1)+54*7-1>=$C9),1,""))
E10: =IF(OR($C10="",$D10=""),"",IF(AND(DATE($B$1,1,1)+(1-1)*7<=$D10,DATE($B$1,1,1)+1*7-1>=$C10),1,"")) | F10: =IF(OR($C10="",$D10=""),"",IF(AND(DATE($B$1,1,1)+(2-1)*7<=$D10,DATE($B$1,1,1)+2*7-1>=$C10),1,"")) | G10: =IF(OR($C10="",$D10=""),"",IF(AND(DATE($B$1,1,1)+(3-1)*7<=$D10,DATE($B$1,1,1)+3*7-1>=$C10),1,"")) | H10: =IF(OR($C10="",$D10=""),"",IF(AND(DATE($B$1,1,1)+(4-1)*7<=$D10,DATE($B$1,1,1)+4*7-1>=$C10),1,"")) | I10: =IF(OR($C10="",$D10=""),"",IF(AND(DATE($B$1,1,1)+(5-1)*7<=$D10,DATE($B$1,1,1)+5*7-1>=$C10),1,"")) | J10: =IF(OR($C10="",$D10=""),"",IF(AND(DATE($B$1,1,1)+(6-1)*7<=$D10,DATE($B$1,1,1)+6*7-1>=$C10),1,"")) | K10: =IF(OR($C10="",$D10=""),"",IF(AND(DATE($B$1,1,1)+(7-1)*7<=$D10,DATE($B$1,1,1)+7*7-1>=$C10),1,"")) | L10: =IF(OR($C10="",$D10=""),"",IF(AND(DATE($B$1,1,1)+(8-1)*7<=$D10,DATE($B$1,1,1)+8*7-1>=$C10),1,"")) | M10: =IF(OR($C10="",$D10=""),"",IF(AND(DATE($B$1,1,1)+(9-1)*7<=$D10,DATE($B$1,1,1)+9*7-1>=$C10),1,"")) | N10: =IF(OR($C10="",$D10=""),"",IF(AND(DATE($B$1,1,1)+(10-1)*7<=$D10,DATE($B$1,1,1)+10*7-1>=$C10),1,"")) | O10: =IF(OR($C10="",$D10=""),"",IF(AND(DATE($B$1,1,1)+(11-1)*7<=$D10,DATE($B$1,1,1)+11*7-1>=$C10),1,"")) | P10: =IF(OR($C10="",$D10=""),"",IF(AND(DATE($B$1,1,1)+(12-1)*7<=$D10,DATE($B$1,1,1)+12*7-1>=$C10),1,"")) | Q10: =IF(OR($C10="",$D10=""),"",IF(AND(DATE($B$1,1,1)+(13-1)*7<=$D10,DATE($B$1,1,1)+13*7-1>=$C10),1,"")) | R10: =IF(OR($C10="",$D10=""),"",IF(AND(DATE($B$1,1,1)+(14-1)*7<=$D10,DATE($B$1,1,1)+14*7-1>=$C10),1,"")) | S10: =IF(OR($C10="",$D10=""),"",IF(AND(DATE($B$1,1,1)+(15-1)*7<=$D10,DATE($B$1,1,1)+15*7-1>=$C10),1,"")) | T10: =IF(OR($C10="",$D10=""),"",IF(AND(DATE($B$1,1,1)+(16-1)*7<=$D10,DATE($B$1,1,1)+16*7-1>=$C10),1,"")) | U10: =IF(OR($C10="",$D10=""),"",IF(AND(DATE($B$1,1,1)+(17-1)*7<=$D10,DATE($B$1,1,1)+17*7-1>=$C10),1,"")) | V10: =IF(OR($C10="",$D10=""),"",IF(AND(DATE($B$1,1,1)+(18-1)*7<=$D10,DATE($B$1,1,1)+18*7-1>=$C10),1,"")) | W10: =IF(OR($C10="",$D10=""),"",IF(AND(DATE($B$1,1,1)+(19-1)*7<=$D10,DATE($B$1,1,1)+19*7-1>=$C10),1,"")) | X10: =IF(OR($C10="",$D10=""),"",IF(AND(DATE($B$1,1,1)+(20-1)*7<=$D10,DATE($B$1,1,1)+20*7-1>=$C10),1,"")) | Y10: =IF(OR($C10="",$D10=""),"",IF(AND(DATE($B$1,1,1)+(21-1)*7<=$D10,DATE($B$1,1,1)+21*7-1>=$C10),1,"")) | Z10: =IF(OR($C10="",$D10=""),"",IF(AND(DATE($B$1,1,1)+(22-1)*7<=$D10,DATE($B$1,1,1)+22*7-1>=$C10),1,"")) | AA10: =IF(OR($C10="",$D10=""),"",IF(AND(DATE($B$1,1,1)+(23-1)*7<=$D10,DATE($B$1,1,1)+23*7-1>=$C10),1,"")) | AB10: =IF(OR($C10="",$D10=""),"",IF(AND(DATE($B$1,1,1)+(24-1)*7<=$D10,DATE($B$1,1,1)+24*7-1>=$C10),1,"")) | AC10: =IF(OR($C10="",$D10=""),"",IF(AND(DATE($B$1,1,1)+(25-1)*7<=$D10,DATE($B$1,1,1)+25*7-1>=$C10),1,"")) | AD10: =IF(OR($C10="",$D10=""),"",IF(AND(DATE($B$1,1,1)+(26-1)*7<=$D10,DATE($B$1,1,1)+26*7-1>=$C10),1,"")) | AE10: =IF(OR($C10="",$D10=""),"",IF(AND(DATE($B$1,1,1)+(27-1)*7<=$D10,DATE($B$1,1,1)+27*7-1>=$C10),1,"")) | AF10: =IF(OR($C10="",$D10=""),"",IF(AND(DATE($B$1,1,1)+(28-1)*7<=$D10,DATE($B$1,1,1)+28*7-1>=$C10),1,"")) | AG10: =IF(OR($C10="",$D10=""),"",IF(AND(DATE($B$1,1,1)+(29-1)*7<=$D10,DATE($B$1,1,1)+29*7-1>=$C10),1,"")) | AH10: =IF(OR($C10="",$D10=""),"",IF(AND(DATE($B$1,1,1)+(30-1)*7<=$D10,DATE($B$1,1,1)+30*7-1>=$C10),1,"")) | AI10: =IF(OR($C10="",$D10=""),"",IF(AND(DATE($B$1,1,1)+(31-1)*7<=$D10,DATE($B$1,1,1)+31*7-1>=$C10),1,"")) | AJ10: =IF(OR($C10="",$D10=""),"",IF(AND(DATE($B$1,1,1)+(32-1)*7<=$D10,DATE($B$1,1,1)+32*7-1>=$C10),1,"")) | AK10: =IF(OR($C10="",$D10=""),"",IF(AND(DATE($B$1,1,1)+(33-1)*7<=$D10,DATE($B$1,1,1)+33*7-1>=$C10),1,"")) | AL10: =IF(OR($C10="",$D10=""),"",IF(AND(DATE($B$1,1,1)+(34-1)*7<=$D10,DATE($B$1,1,1)+34*7-1>=$C10),1,"")) | AM10: =IF(OR($C10="",$D10=""),"",IF(AND(DATE($B$1,1,1)+(35-1)*7<=$D10,DATE($B$1,1,1)+35*7-1>=$C10),1,"")) | AN10: =IF(OR($C10="",$D10=""),"",IF(AND(DATE($B$1,1,1)+(36-1)*7<=$D10,DATE($B$1,1,1)+36*7-1>=$C10),1,"")) | AO10: =IF(OR($C10="",$D10=""),"",IF(AND(DATE($B$1,1,1)+(37-1)*7<=$D10,DATE($B$1,1,1)+37*7-1>=$C10),1,"")) | AP10: =IF(OR($C10="",$D10=""),"",IF(AND(DATE($B$1,1,1)+(38-1)*7<=$D10,DATE($B$1,1,1)+38*7-1>=$C10),1,"")) | AQ10: =IF(OR($C10="",$D10=""),"",IF(AND(DATE($B$1,1,1)+(39-1)*7<=$D10,DATE($B$1,1,1)+39*7-1>=$C10),1,"")) | AR10: =IF(OR($C10="",$D10=""),"",IF(AND(DATE($B$1,1,1)+(40-1)*7<=$D10,DATE($B$1,1,1)+40*7-1>=$C10),1,"")) | AS10: =IF(OR($C10="",$D10=""),"",IF(AND(DATE($B$1,1,1)+(41-1)*7<=$D10,DATE($B$1,1,1)+41*7-1>=$C10),1,"")) | AT10: =IF(OR($C10="",$D10=""),"",IF(AND(DATE($B$1,1,1)+(42-1)*7<=$D10,DATE($B$1,1,1)+42*7-1>=$C10),1,"")) | AU10: =IF(OR($C10="",$D10=""),"",IF(AND(DATE($B$1,1,1)+(43-1)*7<=$D10,DATE($B$1,1,1)+43*7-1>=$C10),1,"")) | AV10: =IF(OR($C10="",$D10=""),"",IF(AND(DATE($B$1,1,1)+(44-1)*7<=$D10,DATE($B$1,1,1)+44*7-1>=$C10),1,"")) | AW10: =IF(OR($C10="",$D10=""),"",IF(AND(DATE($B$1,1,1)+(45-1)*7<=$D10,DATE($B$1,1,1)+45*7-1>=$C10),1,"")) | AX10: =IF(OR($C10="",$D10=""),"",IF(AND(DATE($B$1,1,1)+(46-1)*7<=$D10,DATE($B$1,1,1)+46*7-1>=$C10),1,"")) | AY10: =IF(OR($C10="",$D10=""),"",IF(AND(DATE($B$1,1,1)+(47-1)*7<=$D10,DATE($B$1,1,1)+47*7-1>=$C10),1,"")) | AZ10: =IF(OR($C10="",$D10=""),"",IF(AND(DATE($B$1,1,1)+(48-1)*7<=$D10,DATE($B$1,1,1)+48*7-1>=$C10),1,"")) | BA10: =IF(OR($C10="",$D10=""),"",IF(AND(DATE($B$1,1,1)+(49-1)*7<=$D10,DATE($B$1,1,1)+49*7-1>=$C10),1,"")) | BB10: =IF(OR($C10="",$D10=""),"",IF(AND(DATE($B$1,1,1)+(50-1)*7<=$D10,DATE($B$1,1,1)+50*7-1>=$C10),1,"")) | BC10: =IF(OR($C10="",$D10=""),"",IF(AND(DATE($B$1,1,1)+(51-1)*7<=$D10,DATE($B$1,1,1)+51*7-1>=$C10),1,"")) | BD10: =IF(OR($C10="",$D10=""),"",IF(AND(DATE($B$1,1,1)+(52-1)*7<=$D10,DATE($B$1,1,1)+52*7-1>=$C10),1,"")) | BE10: =IF(OR($C10="",$D10=""),"",IF(AND(DATE($B$1,1,1)+(53-1)*7<=$D10,DATE($B$1,1,1)+53*7-1>=$C10),1,"")) | BF10: =IF(OR($C10="",$D10=""),"",IF(AND(DATE($B$1,1,1)+(54-1)*7<=$D10,DATE($B$1,1,1)+54*7-1>=$C10),1,""))
